/usr/bin/python3: can't find '__main__' module in '/home/Chunar/codes'
  File "/home/Chunar/codes/Monitor_pi/motor_factory/fetch_data_server/socket_server.py", line 26
    t = time.localtime()
                       ^
TabError: inconsistent use of tabs and spaces in indentation
----------------------------------------
Exception happened during processing of request from ('219.217.153.91', 2685)
Traceback (most recent call last):
  File "/home/Chunar/anaconda3/envs/chunar/lib/python3.7/socketserver.py", line 650, in process_request_thread
    self.finish_request(request, client_address)
  File "/home/Chunar/anaconda3/envs/chunar/lib/python3.7/socketserver.py", line 360, in finish_request
    self.RequestHandlerClass(request, client_address, self)
  File "/home/Chunar/anaconda3/envs/chunar/lib/python3.7/socketserver.py", line 720, in __init__
    self.handle()
  File "sockettest.py", line 29, in handle
    data_dict = json.loads(data.decode())
  File "/home/Chunar/anaconda3/envs/chunar/lib/python3.7/json/__init__.py", line 348, in loads
    return _default_decoder.decode(s)
  File "/home/Chunar/anaconda3/envs/chunar/lib/python3.7/json/decoder.py", line 337, in decode
    obj, end = self.raw_decode(s, idx=_w(s, 0).end())
  File "/home/Chunar/anaconda3/envs/chunar/lib/python3.7/json/decoder.py", line 355, in raw_decode
    raise JSONDecodeError("Expecting value", s, err.value) from None
json.decoder.JSONDecodeError: Expecting value: line 1 column 1 (char 0)
----------------------------------------
----------------------------------------
Exception happened during processing of request from ('219.217.153.91', 2707)
Traceback (most recent call last):
  File "/home/Chunar/anaconda3/envs/chunar/lib/python3.7/socketserver.py", line 650, in process_request_thread
    self.finish_request(request, client_address)
  File "/home/Chunar/anaconda3/envs/chunar/lib/python3.7/socketserver.py", line 360, in finish_request
    self.RequestHandlerClass(request, client_address, self)
  File "/home/Chunar/anaconda3/envs/chunar/lib/python3.7/socketserver.py", line 720, in __init__
    self.handle()
  File "sockettest.py", line 29, in handle
    data_dict = json.loads(data.decode())
  File "/home/Chunar/anaconda3/envs/chunar/lib/python3.7/json/__init__.py", line 348, in loads
    return _default_decoder.decode(s)
  File "/home/Chunar/anaconda3/envs/chunar/lib/python3.7/json/decoder.py", line 337, in decode
    obj, end = self.raw_decode(s, idx=_w(s, 0).end())
  File "/home/Chunar/anaconda3/envs/chunar/lib/python3.7/json/decoder.py", line 355, in raw_decode
    raise JSONDecodeError("Expecting value", s, err.value) from None
json.decoder.JSONDecodeError: Expecting value: line 1 column 1 (char 0)
----------------------------------------
----------------------------------------
Exception happened during processing of request from ('219.217.153.91', 2708)
Traceback (most recent call last):
  File "/home/Chunar/anaconda3/envs/chunar/lib/python3.7/socketserver.py", line 650, in process_request_thread
    self.finish_request(request, client_address)
  File "/home/Chunar/anaconda3/envs/chunar/lib/python3.7/socketserver.py", line 360, in finish_request
    self.RequestHandlerClass(request, client_address, self)
  File "/home/Chunar/anaconda3/envs/chunar/lib/python3.7/socketserver.py", line 720, in __init__
    self.handle()
  File "sockettest.py", line 29, in handle
    data_dict = json.loads(data.decode())
  File "/home/Chunar/anaconda3/envs/chunar/lib/python3.7/json/__init__.py", line 348, in loads
    return _default_decoder.decode(s)
  File "/home/Chunar/anaconda3/envs/chunar/lib/python3.7/json/decoder.py", line 337, in decode
    obj, end = self.raw_decode(s, idx=_w(s, 0).end())
  File "/home/Chunar/anaconda3/envs/chunar/lib/python3.7/json/decoder.py", line 355, in raw_decode
    raise JSONDecodeError("Expecting value", s, err.value) from None
json.decoder.JSONDecodeError: Expecting value: line 1 column 1 (char 0)
----------------------------------------
----------------------------------------
Exception happened during processing of request from ('47.101.63.151', 44427)
Traceback (most recent call last):
  File "/home/Chunar/anaconda3/envs/chunar/lib/python3.7/socketserver.py", line 650, in process_request_thread
    self.finish_request(request, client_address)
  File "/home/Chunar/anaconda3/envs/chunar/lib/python3.7/socketserver.py", line 360, in finish_request
    self.RequestHandlerClass(request, client_address, self)
  File "/home/Chunar/anaconda3/envs/chunar/lib/python3.7/socketserver.py", line 720, in __init__
    self.handle()
  File "sockettest.py", line 29, in handle
    data_dict = json.loads(data.decode())
  File "/home/Chunar/anaconda3/envs/chunar/lib/python3.7/json/__init__.py", line 348, in loads
    return _default_decoder.decode(s)
  File "/home/Chunar/anaconda3/envs/chunar/lib/python3.7/json/decoder.py", line 337, in decode
    obj, end = self.raw_decode(s, idx=_w(s, 0).end())
  File "/home/Chunar/anaconda3/envs/chunar/lib/python3.7/json/decoder.py", line 355, in raw_decode
    raise JSONDecodeError("Expecting value", s, err.value) from None
json.decoder.JSONDecodeError: Expecting value: line 1 column 1 (char 0)
----------------------------------------
----------------------------------------
Exception happened during processing of request from ('219.217.153.91', 10785)
Traceback (most recent call last):
  File "/home/Chunar/anaconda3/envs/chunar/lib/python3.7/socketserver.py", line 650, in process_request_thread
    self.finish_request(request, client_address)
  File "/home/Chunar/anaconda3/envs/chunar/lib/python3.7/socketserver.py", line 360, in finish_request
    self.RequestHandlerClass(request, client_address, self)
  File "/home/Chunar/anaconda3/envs/chunar/lib/python3.7/socketserver.py", line 720, in __init__
    self.handle()
  File "sockettest.py", line 29, in handle
    data_dict = json.loads(data.decode())
  File "/home/Chunar/anaconda3/envs/chunar/lib/python3.7/json/__init__.py", line 348, in loads
    return _default_decoder.decode(s)
  File "/home/Chunar/anaconda3/envs/chunar/lib/python3.7/json/decoder.py", line 337, in decode
    obj, end = self.raw_decode(s, idx=_w(s, 0).end())
  File "/home/Chunar/anaconda3/envs/chunar/lib/python3.7/json/decoder.py", line 355, in raw_decode
    raise JSONDecodeError("Expecting value", s, err.value) from None
json.decoder.JSONDecodeError: Expecting value: line 1 column 1 (char 0)
----------------------------------------
----------------------------------------
Exception happened during processing of request from ('219.217.153.91', 10800)
Traceback (most recent call last):
  File "/home/Chunar/anaconda3/envs/chunar/lib/python3.7/socketserver.py", line 650, in process_request_thread
    self.finish_request(request, client_address)
  File "/home/Chunar/anaconda3/envs/chunar/lib/python3.7/socketserver.py", line 360, in finish_request
    self.RequestHandlerClass(request, client_address, self)
  File "/home/Chunar/anaconda3/envs/chunar/lib/python3.7/socketserver.py", line 720, in __init__
    self.handle()
  File "sockettest.py", line 29, in handle
    data_dict = json.loads(data.decode())
  File "/home/Chunar/anaconda3/envs/chunar/lib/python3.7/json/__init__.py", line 348, in loads
    return _default_decoder.decode(s)
  File "/home/Chunar/anaconda3/envs/chunar/lib/python3.7/json/decoder.py", line 337, in decode
    obj, end = self.raw_decode(s, idx=_w(s, 0).end())
  File "/home/Chunar/anaconda3/envs/chunar/lib/python3.7/json/decoder.py", line 355, in raw_decode
    raise JSONDecodeError("Expecting value", s, err.value) from None
json.decoder.JSONDecodeError: Expecting value: line 1 column 1 (char 0)
----------------------------------------
----------------------------------------
Exception happened during processing of request from ('219.217.153.91', 10905)
Traceback (most recent call last):
  File "/home/Chunar/anaconda3/envs/chunar/lib/python3.7/socketserver.py", line 650, in process_request_thread
    self.finish_request(request, client_address)
  File "/home/Chunar/anaconda3/envs/chunar/lib/python3.7/socketserver.py", line 360, in finish_request
    self.RequestHandlerClass(request, client_address, self)
  File "/home/Chunar/anaconda3/envs/chunar/lib/python3.7/socketserver.py", line 720, in __init__
    self.handle()
  File "sockettest.py", line 29, in handle
    data_dict = json.loads(data.decode())
  File "/home/Chunar/anaconda3/envs/chunar/lib/python3.7/json/__init__.py", line 348, in loads
    return _default_decoder.decode(s)
  File "/home/Chunar/anaconda3/envs/chunar/lib/python3.7/json/decoder.py", line 340, in decode
    raise JSONDecodeError("Extra data", s, end)
json.decoder.JSONDecodeError: Extra data: line 1 column 227 (char 226)
----------------------------------------
----------------------------------------
Exception happened during processing of request from ('219.217.153.91', 10913)
Traceback (most recent call last):
  File "/home/Chunar/anaconda3/envs/chunar/lib/python3.7/socketserver.py", line 650, in process_request_thread
    self.finish_request(request, client_address)
  File "/home/Chunar/anaconda3/envs/chunar/lib/python3.7/socketserver.py", line 360, in finish_request
    self.RequestHandlerClass(request, client_address, self)
  File "/home/Chunar/anaconda3/envs/chunar/lib/python3.7/socketserver.py", line 720, in __init__
    self.handle()
  File "sockettest.py", line 29, in handle
    data_dict = json.loads(data.decode())
  File "/home/Chunar/anaconda3/envs/chunar/lib/python3.7/json/__init__.py", line 348, in loads
    return _default_decoder.decode(s)
  File "/home/Chunar/anaconda3/envs/chunar/lib/python3.7/json/decoder.py", line 340, in decode
    raise JSONDecodeError("Extra data", s, end)
json.decoder.JSONDecodeError: Extra data: line 1 column 227 (char 226)
----------------------------------------
----------------------------------------
Exception happened during processing of request from ('219.217.153.91', 10922)
Traceback (most recent call last):
  File "/home/Chunar/anaconda3/envs/chunar/lib/python3.7/socketserver.py", line 650, in process_request_thread
    self.finish_request(request, client_address)
  File "/home/Chunar/anaconda3/envs/chunar/lib/python3.7/socketserver.py", line 360, in finish_request
    self.RequestHandlerClass(request, client_address, self)
  File "/home/Chunar/anaconda3/envs/chunar/lib/python3.7/socketserver.py", line 720, in __init__
    self.handle()
  File "sockettest.py", line 29, in handle
    data_dict = json.loads(data.decode())
  File "/home/Chunar/anaconda3/envs/chunar/lib/python3.7/json/__init__.py", line 348, in loads
    return _default_decoder.decode(s)
  File "/home/Chunar/anaconda3/envs/chunar/lib/python3.7/json/decoder.py", line 340, in decode
    raise JSONDecodeError("Extra data", s, end)
json.decoder.JSONDecodeError: Extra data: line 1 column 227 (char 226)
----------------------------------------
----------------------------------------
Exception happened during processing of request from ('219.217.153.91', 10929)
Traceback (most recent call last):
  File "/home/Chunar/anaconda3/envs/chunar/lib/python3.7/socketserver.py", line 650, in process_request_thread
    self.finish_request(request, client_address)
  File "/home/Chunar/anaconda3/envs/chunar/lib/python3.7/socketserver.py", line 360, in finish_request
    self.RequestHandlerClass(request, client_address, self)
  File "/home/Chunar/anaconda3/envs/chunar/lib/python3.7/socketserver.py", line 720, in __init__
    self.handle()
  File "sockettest.py", line 29, in handle
    data_dict = json.loads(data.decode())
  File "/home/Chunar/anaconda3/envs/chunar/lib/python3.7/json/__init__.py", line 348, in loads
    return _default_decoder.decode(s)
  File "/home/Chunar/anaconda3/envs/chunar/lib/python3.7/json/decoder.py", line 340, in decode
    raise JSONDecodeError("Extra data", s, end)
json.decoder.JSONDecodeError: Extra data: line 1 column 227 (char 226)
----------------------------------------
----------------------------------------
Exception happened during processing of request from ('219.217.153.91', 10934)
Traceback (most recent call last):
  File "/home/Chunar/anaconda3/envs/chunar/lib/python3.7/socketserver.py", line 650, in process_request_thread
    self.finish_request(request, client_address)
  File "/home/Chunar/anaconda3/envs/chunar/lib/python3.7/socketserver.py", line 360, in finish_request
    self.RequestHandlerClass(request, client_address, self)
  File "/home/Chunar/anaconda3/envs/chunar/lib/python3.7/socketserver.py", line 720, in __init__
    self.handle()
  File "sockettest.py", line 29, in handle
    data_dict = json.loads(data.decode())
  File "/home/Chunar/anaconda3/envs/chunar/lib/python3.7/json/__init__.py", line 348, in loads
    return _default_decoder.decode(s)
  File "/home/Chunar/anaconda3/envs/chunar/lib/python3.7/json/decoder.py", line 340, in decode
    raise JSONDecodeError("Extra data", s, end)
json.decoder.JSONDecodeError: Extra data: line 1 column 227 (char 226)
----------------------------------------
----------------------------------------
Exception happened during processing of request from ('219.217.153.91', 10941)
Traceback (most recent call last):
  File "/home/Chunar/anaconda3/envs/chunar/lib/python3.7/socketserver.py", line 650, in process_request_thread
    self.finish_request(request, client_address)
  File "/home/Chunar/anaconda3/envs/chunar/lib/python3.7/socketserver.py", line 360, in finish_request
    self.RequestHandlerClass(request, client_address, self)
  File "/home/Chunar/anaconda3/envs/chunar/lib/python3.7/socketserver.py", line 720, in __init__
    self.handle()
  File "sockettest.py", line 29, in handle
    data_dict = json.loads(data.decode())
  File "/home/Chunar/anaconda3/envs/chunar/lib/python3.7/json/__init__.py", line 348, in loads
    return _default_decoder.decode(s)
  File "/home/Chunar/anaconda3/envs/chunar/lib/python3.7/json/decoder.py", line 340, in decode
    raise JSONDecodeError("Extra data", s, end)
json.decoder.JSONDecodeError: Extra data: line 1 column 227 (char 226)
----------------------------------------
----------------------------------------
Exception happened during processing of request from ('219.217.153.91', 10973)
Traceback (most recent call last):
  File "/home/Chunar/anaconda3/envs/chunar/lib/python3.7/socketserver.py", line 650, in process_request_thread
    self.finish_request(request, client_address)
  File "/home/Chunar/anaconda3/envs/chunar/lib/python3.7/socketserver.py", line 360, in finish_request
    self.RequestHandlerClass(request, client_address, self)
  File "/home/Chunar/anaconda3/envs/chunar/lib/python3.7/socketserver.py", line 720, in __init__
    self.handle()
  File "sockettest.py", line 29, in handle
    data_dict = json.loads(data.decode())
  File "/home/Chunar/anaconda3/envs/chunar/lib/python3.7/json/__init__.py", line 348, in loads
    return _default_decoder.decode(s)
  File "/home/Chunar/anaconda3/envs/chunar/lib/python3.7/json/decoder.py", line 340, in decode
    raise JSONDecodeError("Extra data", s, end)
json.decoder.JSONDecodeError: Extra data: line 1 column 227 (char 226)
----------------------------------------
----------------------------------------
Exception happened during processing of request from ('219.217.153.91', 10996)
Traceback (most recent call last):
  File "/home/Chunar/anaconda3/envs/chunar/lib/python3.7/socketserver.py", line 650, in process_request_thread
    self.finish_request(request, client_address)
  File "/home/Chunar/anaconda3/envs/chunar/lib/python3.7/socketserver.py", line 360, in finish_request
    self.RequestHandlerClass(request, client_address, self)
  File "/home/Chunar/anaconda3/envs/chunar/lib/python3.7/socketserver.py", line 720, in __init__
    self.handle()
  File "sockettest.py", line 29, in handle
    data_dict = json.loads(data.decode())
  File "/home/Chunar/anaconda3/envs/chunar/lib/python3.7/json/__init__.py", line 348, in loads
    return _default_decoder.decode(s)
  File "/home/Chunar/anaconda3/envs/chunar/lib/python3.7/json/decoder.py", line 340, in decode
    raise JSONDecodeError("Extra data", s, end)
json.decoder.JSONDecodeError: Extra data: line 1 column 227 (char 226)
----------------------------------------
----------------------------------------
Exception happened during processing of request from ('219.217.153.91', 11007)
Traceback (most recent call last):
  File "/home/Chunar/anaconda3/envs/chunar/lib/python3.7/socketserver.py", line 650, in process_request_thread
    self.finish_request(request, client_address)
  File "/home/Chunar/anaconda3/envs/chunar/lib/python3.7/socketserver.py", line 360, in finish_request
    self.RequestHandlerClass(request, client_address, self)
  File "/home/Chunar/anaconda3/envs/chunar/lib/python3.7/socketserver.py", line 720, in __init__
    self.handle()
  File "sockettest.py", line 29, in handle
    data_dict = json.loads(data.decode())
  File "/home/Chunar/anaconda3/envs/chunar/lib/python3.7/json/__init__.py", line 348, in loads
    return _default_decoder.decode(s)
  File "/home/Chunar/anaconda3/envs/chunar/lib/python3.7/json/decoder.py", line 340, in decode
    raise JSONDecodeError("Extra data", s, end)
json.decoder.JSONDecodeError: Extra data: line 1 column 227 (char 226)
----------------------------------------
----------------------------------------
Exception happened during processing of request from ('219.217.153.91', 11012)
Traceback (most recent call last):
  File "/home/Chunar/anaconda3/envs/chunar/lib/python3.7/socketserver.py", line 650, in process_request_thread
    self.finish_request(request, client_address)
  File "/home/Chunar/anaconda3/envs/chunar/lib/python3.7/socketserver.py", line 360, in finish_request
    self.RequestHandlerClass(request, client_address, self)
  File "/home/Chunar/anaconda3/envs/chunar/lib/python3.7/socketserver.py", line 720, in __init__
    self.handle()
  File "sockettest.py", line 29, in handle
    data_dict = json.loads(data.decode())
  File "/home/Chunar/anaconda3/envs/chunar/lib/python3.7/json/__init__.py", line 348, in loads
    return _default_decoder.decode(s)
  File "/home/Chunar/anaconda3/envs/chunar/lib/python3.7/json/decoder.py", line 340, in decode
    raise JSONDecodeError("Extra data", s, end)
json.decoder.JSONDecodeError: Extra data: line 1 column 227 (char 226)
----------------------------------------
----------------------------------------
Exception happened during processing of request from ('219.217.153.91', 11017)
Traceback (most recent call last):
  File "/home/Chunar/anaconda3/envs/chunar/lib/python3.7/socketserver.py", line 650, in process_request_thread
    self.finish_request(request, client_address)
  File "/home/Chunar/anaconda3/envs/chunar/lib/python3.7/socketserver.py", line 360, in finish_request
    self.RequestHandlerClass(request, client_address, self)
  File "/home/Chunar/anaconda3/envs/chunar/lib/python3.7/socketserver.py", line 720, in __init__
    self.handle()
  File "sockettest.py", line 29, in handle
    data_dict = json.loads(data.decode())
  File "/home/Chunar/anaconda3/envs/chunar/lib/python3.7/json/__init__.py", line 348, in loads
    return _default_decoder.decode(s)
  File "/home/Chunar/anaconda3/envs/chunar/lib/python3.7/json/decoder.py", line 340, in decode
    raise JSONDecodeError("Extra data", s, end)
json.decoder.JSONDecodeError: Extra data: line 1 column 227 (char 226)
----------------------------------------
----------------------------------------
Exception happened during processing of request from ('219.217.153.91', 11020)
Traceback (most recent call last):
  File "/home/Chunar/anaconda3/envs/chunar/lib/python3.7/socketserver.py", line 650, in process_request_thread
    self.finish_request(request, client_address)
  File "/home/Chunar/anaconda3/envs/chunar/lib/python3.7/socketserver.py", line 360, in finish_request
    self.RequestHandlerClass(request, client_address, self)
  File "/home/Chunar/anaconda3/envs/chunar/lib/python3.7/socketserver.py", line 720, in __init__
    self.handle()
  File "sockettest.py", line 29, in handle
    data_dict = json.loads(data.decode())
  File "/home/Chunar/anaconda3/envs/chunar/lib/python3.7/json/__init__.py", line 348, in loads
    return _default_decoder.decode(s)
  File "/home/Chunar/anaconda3/envs/chunar/lib/python3.7/json/decoder.py", line 340, in decode
    raise JSONDecodeError("Extra data", s, end)
json.decoder.JSONDecodeError: Extra data: line 1 column 227 (char 226)
----------------------------------------
----------------------------------------
Exception happened during processing of request from ('219.217.153.91', 11104)
Traceback (most recent call last):
  File "/home/Chunar/anaconda3/envs/chunar/lib/python3.7/socketserver.py", line 650, in process_request_thread
    self.finish_request(request, client_address)
  File "/home/Chunar/anaconda3/envs/chunar/lib/python3.7/socketserver.py", line 360, in finish_request
    self.RequestHandlerClass(request, client_address, self)
  File "/home/Chunar/anaconda3/envs/chunar/lib/python3.7/socketserver.py", line 720, in __init__
    self.handle()
  File "sockettest.py", line 29, in handle
    data_dict = json.loads(data.decode())
  File "/home/Chunar/anaconda3/envs/chunar/lib/python3.7/json/__init__.py", line 348, in loads
    return _default_decoder.decode(s)
  File "/home/Chunar/anaconda3/envs/chunar/lib/python3.7/json/decoder.py", line 337, in decode
    obj, end = self.raw_decode(s, idx=_w(s, 0).end())
  File "/home/Chunar/anaconda3/envs/chunar/lib/python3.7/json/decoder.py", line 355, in raw_decode
    raise JSONDecodeError("Expecting value", s, err.value) from None
json.decoder.JSONDecodeError: Expecting value: line 1 column 1 (char 0)
----------------------------------------
----------------------------------------
Exception happened during processing of request from ('219.217.153.91', 11133)
Traceback (most recent call last):
  File "/home/Chunar/anaconda3/envs/chunar/lib/python3.7/socketserver.py", line 650, in process_request_thread
    self.finish_request(request, client_address)
  File "/home/Chunar/anaconda3/envs/chunar/lib/python3.7/socketserver.py", line 360, in finish_request
    self.RequestHandlerClass(request, client_address, self)
  File "/home/Chunar/anaconda3/envs/chunar/lib/python3.7/socketserver.py", line 720, in __init__
    self.handle()
  File "sockettest.py", line 29, in handle
    data_dict = json.loads(data.decode())
  File "/home/Chunar/anaconda3/envs/chunar/lib/python3.7/json/__init__.py", line 348, in loads
    return _default_decoder.decode(s)
  File "/home/Chunar/anaconda3/envs/chunar/lib/python3.7/json/decoder.py", line 337, in decode
    obj, end = self.raw_decode(s, idx=_w(s, 0).end())
  File "/home/Chunar/anaconda3/envs/chunar/lib/python3.7/json/decoder.py", line 355, in raw_decode
    raise JSONDecodeError("Expecting value", s, err.value) from None
json.decoder.JSONDecodeError: Expecting value: line 1 column 1 (char 0)
----------------------------------------
----------------------------------------
Exception happened during processing of request from ('219.217.153.91', 11134)
Traceback (most recent call last):
  File "/home/Chunar/anaconda3/envs/chunar/lib/python3.7/socketserver.py", line 650, in process_request_thread
    self.finish_request(request, client_address)
  File "/home/Chunar/anaconda3/envs/chunar/lib/python3.7/socketserver.py", line 360, in finish_request
    self.RequestHandlerClass(request, client_address, self)
  File "/home/Chunar/anaconda3/envs/chunar/lib/python3.7/socketserver.py", line 720, in __init__
    self.handle()
  File "sockettest.py", line 29, in handle
    data_dict = json.loads(data.decode())
  File "/home/Chunar/anaconda3/envs/chunar/lib/python3.7/json/__init__.py", line 348, in loads
    return _default_decoder.decode(s)
  File "/home/Chunar/anaconda3/envs/chunar/lib/python3.7/json/decoder.py", line 337, in decode
    obj, end = self.raw_decode(s, idx=_w(s, 0).end())
  File "/home/Chunar/anaconda3/envs/chunar/lib/python3.7/json/decoder.py", line 355, in raw_decode
    raise JSONDecodeError("Expecting value", s, err.value) from None
json.decoder.JSONDecodeError: Expecting value: line 1 column 1 (char 0)
----------------------------------------
----------------------------------------
Exception happened during processing of request from ('219.217.153.91', 11135)
Traceback (most recent call last):
  File "/home/Chunar/anaconda3/envs/chunar/lib/python3.7/socketserver.py", line 650, in process_request_thread
    self.finish_request(request, client_address)
  File "/home/Chunar/anaconda3/envs/chunar/lib/python3.7/socketserver.py", line 360, in finish_request
    self.RequestHandlerClass(request, client_address, self)
  File "/home/Chunar/anaconda3/envs/chunar/lib/python3.7/socketserver.py", line 720, in __init__
    self.handle()
  File "sockettest.py", line 29, in handle
    data_dict = json.loads(data.decode())
  File "/home/Chunar/anaconda3/envs/chunar/lib/python3.7/json/__init__.py", line 348, in loads
    return _default_decoder.decode(s)
