DEBUG:asyncio:Using selector: EpollSelector
DEBUG:asyncio:Using selector: EpollSelector
INFO:root:Socket served at time: Thu Oct 24 08:42:50 2019 with: ('219.217.154.114', 9709)
INFO:root:successfully connected ...
INFO:root:successfully connected ...
INFO:root:successfully connected ...
INFO:root:successfully connected ...
INFO:root:Server finished
INFO:root:*************************
INFO:root:Socket served at time: Fri Oct 25 14:54:36 2019 with: ('219.217.155.102', 12108)
INFO:root:successfully connected ...
INFO:root:Server finished
INFO:root:*************************
DEBUG:asyncio:Using selector: EpollSelector
INFO:root:Socket served at time: Fri Oct 25 15:04:15 2019 with: ('219.217.155.102', 12467)
INFO:root:successfully connected ...
INFO:root:successfully connected ...
INFO:root:successfully connected ...
INFO:root:successfully connected ...
INFO:root:Server finished
INFO:root:*************************
DEBUG:asyncio:Using selector: EpollSelector
INFO:root:Socket served at time: Fri Oct 25 15:35:21 2019 with: ('219.217.155.102', 13230)
INFO:root:successfully connected ...
INFO:root:successfully connected ...
INFO:root:successfully connected ...
INFO:root:successfully connected ...
INFO:root:Server finished
INFO:root:*************************
DEBUG:asyncio:Using selector: EpollSelector
INFO:root:Socket served at time: Fri Oct 25 18:29:03 2019 with: ('58.213.153.13', 50716)
INFO:root:successfully connected ...
ERROR:tornado.application:Exception in callback functools.partial(<function TCPServer._handle_connection.<locals>.<lambda> at 0x7fc51a8cb200>, <Future finished exception=JSONDecodeError('Expecting value: line 3 column 1 (char 4)')>)
Traceback (most recent call last):
  File "/usr/local/python3/lib/python3.7/site-packages/tornado/ioloop.py", line 743, in _run_callback
    ret = callback()
  File "/usr/local/python3/lib/python3.7/site-packages/tornado/tcpserver.py", line 327, in <lambda>
    gen.convert_yielded(future), lambda f: f.result()
  File "/usr/local/python3/lib/python3.7/site-packages/tornado/gen.py", line 748, in run
    yielded = self.gen.send(value)
  File "/home/Chunar/codes/Monitor_pi/motor_factory/fetch_data_server/socket_server.py", line 36, in handle_stream
    data_dict = json.loads(data.decode())
  File "/usr/local/python3/lib/python3.7/json/__init__.py", line 348, in loads
    return _default_decoder.decode(s)
  File "/usr/local/python3/lib/python3.7/json/decoder.py", line 337, in decode
    obj, end = self.raw_decode(s, idx=_w(s, 0).end())
  File "/usr/local/python3/lib/python3.7/json/decoder.py", line 355, in raw_decode
    raise JSONDecodeError("Expecting value", s, err.value) from None
json.decoder.JSONDecodeError: Expecting value: line 3 column 1 (char 4)
INFO:root:Socket served at time: Fri Oct 25 18:29:15 2019 with: ('58.213.153.13', 50875)
INFO:root:successfully connected ...
ERROR:tornado.application:Exception in callback functools.partial(<function TCPServer._handle_connection.<locals>.<lambda> at 0x7fc51a8883b0>, <Future finished exception=JSONDecodeError('Expecting value: line 1 column 1 (char 0)')>)
Traceback (most recent call last):
  File "/usr/local/python3/lib/python3.7/site-packages/tornado/ioloop.py", line 743, in _run_callback
    ret = callback()
  File "/usr/local/python3/lib/python3.7/site-packages/tornado/tcpserver.py", line 327, in <lambda>
    gen.convert_yielded(future), lambda f: f.result()
  File "/usr/local/python3/lib/python3.7/site-packages/tornado/gen.py", line 748, in run
    yielded = self.gen.send(value)
  File "/home/Chunar/codes/Monitor_pi/motor_factory/fetch_data_server/socket_server.py", line 36, in handle_stream
    data_dict = json.loads(data.decode())
  File "/usr/local/python3/lib/python3.7/json/__init__.py", line 348, in loads
    return _default_decoder.decode(s)
  File "/usr/local/python3/lib/python3.7/json/decoder.py", line 337, in decode
    obj, end = self.raw_decode(s, idx=_w(s, 0).end())
  File "/usr/local/python3/lib/python3.7/json/decoder.py", line 355, in raw_decode
    raise JSONDecodeError("Expecting value", s, err.value) from None
json.decoder.JSONDecodeError: Expecting value: line 1 column 1 (char 0)
INFO:root:Socket served at time: Fri Oct 25 18:29:20 2019 with: ('58.213.153.13', 50944)
INFO:root:successfully connected ...
ERROR:tornado.application:Exception in callback functools.partial(<function TCPServer._handle_connection.<locals>.<lambda> at 0x7fc51a888560>, <Future finished exception=JSONDecodeError('Expecting value: line 1 column 1 (char 0)')>)
Traceback (most recent call last):
  File "/usr/local/python3/lib/python3.7/site-packages/tornado/ioloop.py", line 743, in _run_callback
    ret = callback()
  File "/usr/local/python3/lib/python3.7/site-packages/tornado/tcpserver.py", line 327, in <lambda>
    gen.convert_yielded(future), lambda f: f.result()
  File "/usr/local/python3/lib/python3.7/site-packages/tornado/gen.py", line 748, in run
    yielded = self.gen.send(value)
  File "/home/Chunar/codes/Monitor_pi/motor_factory/fetch_data_server/socket_server.py", line 36, in handle_stream
    data_dict = json.loads(data.decode())
  File "/usr/local/python3/lib/python3.7/json/__init__.py", line 348, in loads
    return _default_decoder.decode(s)
  File "/usr/local/python3/lib/python3.7/json/decoder.py", line 337, in decode
    obj, end = self.raw_decode(s, idx=_w(s, 0).end())
  File "/usr/local/python3/lib/python3.7/json/decoder.py", line 355, in raw_decode
    raise JSONDecodeError("Expecting value", s, err.value) from None
json.decoder.JSONDecodeError: Expecting value: line 1 column 1 (char 0)
INFO:root:Socket served at time: Fri Oct 25 18:29:25 2019 with: ('58.213.153.13', 50981)
INFO:root:successfully connected ...
ERROR:tornado.application:Exception in callback functools.partial(<function TCPServer._handle_connection.<locals>.<lambda> at 0x7fc51a888710>, <Future finished exception=JSONDecodeError('Expecting value: line 1 column 1 (char 0)')>)
Traceback (most recent call last):
  File "/usr/local/python3/lib/python3.7/site-packages/tornado/ioloop.py", line 743, in _run_callback
    ret = callback()
  File "/usr/local/python3/lib/python3.7/site-packages/tornado/tcpserver.py", line 327, in <lambda>
    gen.convert_yielded(future), lambda f: f.result()
  File "/usr/local/python3/lib/python3.7/site-packages/tornado/gen.py", line 748, in run
    yielded = self.gen.send(value)
  File "/home/Chunar/codes/Monitor_pi/motor_factory/fetch_data_server/socket_server.py", line 36, in handle_stream
    data_dict = json.loads(data.decode())
  File "/usr/local/python3/lib/python3.7/json/__init__.py", line 348, in loads
    return _default_decoder.decode(s)
  File "/usr/local/python3/lib/python3.7/json/decoder.py", line 337, in decode
    obj, end = self.raw_decode(s, idx=_w(s, 0).end())
  File "/usr/local/python3/lib/python3.7/json/decoder.py", line 355, in raw_decode
    raise JSONDecodeError("Expecting value", s, err.value) from None
json.decoder.JSONDecodeError: Expecting value: line 1 column 1 (char 0)
INFO:root:Socket served at time: Fri Oct 25 18:29:30 2019 with: ('58.213.153.13', 51015)
INFO:root:successfully connected ...
ERROR:tornado.application:Exception in callback functools.partial(<function TCPServer._handle_connection.<locals>.<lambda> at 0x7fc51ab53ef0>, <Future finished exception=UnicodeDecodeError('utf-8', b'\x80\x00\x00(r\xfe\x1d\x13\x00\x00\x00\x00\x00\x00\x00\x02\x00\x01\x86\xa0\x00\x01\x97|\x00\x00\x00\x00\x00\x00\x00\x00\x00\x00\x00\x00\x00\x00\x00\x00\x00\x00\x00\x00', 0, 1, 'invalid start byte')>)
Traceback (most recent call last):
  File "/usr/local/python3/lib/python3.7/site-packages/tornado/ioloop.py", line 743, in _run_callback
    ret = callback()
  File "/usr/local/python3/lib/python3.7/site-packages/tornado/tcpserver.py", line 327, in <lambda>
    gen.convert_yielded(future), lambda f: f.result()
  File "/usr/local/python3/lib/python3.7/site-packages/tornado/gen.py", line 748, in run
    yielded = self.gen.send(value)
  File "/home/Chunar/codes/Monitor_pi/motor_factory/fetch_data_server/socket_server.py", line 36, in handle_stream
    data_dict = json.loads(data.decode())
UnicodeDecodeError: 'utf-8' codec can't decode byte 0x80 in position 0: invalid start byte
INFO:root:Socket served at time: Fri Oct 25 18:29:35 2019 with: ('58.213.153.13', 51060)
INFO:root:successfully connected ...
ERROR:tornado.application:Exception in callback functools.partial(<function TCPServer._handle_connection.<locals>.<lambda> at 0x7fc51a888830>, <Future finished exception=JSONDecodeError('Expecting value: line 1 column 1 (char 0)')>)
Traceback (most recent call last):
  File "/usr/local/python3/lib/python3.7/site-packages/tornado/ioloop.py", line 743, in _run_callback
    ret = callback()
  File "/usr/local/python3/lib/python3.7/site-packages/tornado/tcpserver.py", line 327, in <lambda>
    gen.convert_yielded(future), lambda f: f.result()
  File "/usr/local/python3/lib/python3.7/site-packages/tornado/gen.py", line 748, in run
    yielded = self.gen.send(value)
  File "/home/Chunar/codes/Monitor_pi/motor_factory/fetch_data_server/socket_server.py", line 36, in handle_stream
    data_dict = json.loads(data.decode())
  File "/usr/local/python3/lib/python3.7/json/__init__.py", line 348, in loads
    return _default_decoder.decode(s)
  File "/usr/local/python3/lib/python3.7/json/decoder.py", line 337, in decode
    obj, end = self.raw_decode(s, idx=_w(s, 0).end())
  File "/usr/local/python3/lib/python3.7/json/decoder.py", line 355, in raw_decode
    raise JSONDecodeError("Expecting value", s, err.value) from None
json.decoder.JSONDecodeError: Expecting value: line 1 column 1 (char 0)
INFO:root:Socket served at time: Fri Oct 25 18:29:40 2019 with: ('58.213.153.13', 51102)
INFO:root:successfully connected ...
ERROR:tornado.application:Exception in callback functools.partial(<function TCPServer._handle_connection.<locals>.<lambda> at 0x7fc51a888560>, <Future finished exception=JSONDecodeError('Expecting value: line 1 column 1 (char 0)')>)
Traceback (most recent call last):
  File "/usr/local/python3/lib/python3.7/site-packages/tornado/ioloop.py", line 743, in _run_callback
    ret = callback()
  File "/usr/local/python3/lib/python3.7/site-packages/tornado/tcpserver.py", line 327, in <lambda>
    gen.convert_yielded(future), lambda f: f.result()
  File "/usr/local/python3/lib/python3.7/site-packages/tornado/gen.py", line 748, in run
    yielded = self.gen.send(value)
  File "/home/Chunar/codes/Monitor_pi/motor_factory/fetch_data_server/socket_server.py", line 36, in handle_stream
    data_dict = json.loads(data.decode())
  File "/usr/local/python3/lib/python3.7/json/__init__.py", line 348, in loads
    return _default_decoder.decode(s)
  File "/usr/local/python3/lib/python3.7/json/decoder.py", line 337, in decode
    obj, end = self.raw_decode(s, idx=_w(s, 0).end())
  File "/usr/local/python3/lib/python3.7/json/decoder.py", line 355, in raw_decode
    raise JSONDecodeError("Expecting value", s, err.value) from None
json.decoder.JSONDecodeError: Expecting value: line 1 column 1 (char 0)
INFO:root:Socket served at time: Fri Oct 25 18:29:45 2019 with: ('58.213.153.13', 51140)
INFO:root:successfully connected ...
ERROR:tornado.application:Exception in callback functools.partial(<function TCPServer._handle_connection.<locals>.<lambda> at 0x7fc51a8887a0>, <Future finished exception=JSONDecodeError('Expecting value: line 1 column 1 (char 0)')>)
Traceback (most recent call last):
  File "/usr/local/python3/lib/python3.7/site-packages/tornado/ioloop.py", line 743, in _run_callback
    ret = callback()
  File "/usr/local/python3/lib/python3.7/site-packages/tornado/tcpserver.py", line 327, in <lambda>
    gen.convert_yielded(future), lambda f: f.result()
  File "/usr/local/python3/lib/python3.7/site-packages/tornado/gen.py", line 748, in run
    yielded = self.gen.send(value)
  File "/home/Chunar/codes/Monitor_pi/motor_factory/fetch_data_server/socket_server.py", line 36, in handle_stream
    data_dict = json.loads(data.decode())
  File "/usr/local/python3/lib/python3.7/json/__init__.py", line 348, in loads
    return _default_decoder.decode(s)
  File "/usr/local/python3/lib/python3.7/json/decoder.py", line 337, in decode
    obj, end = self.raw_decode(s, idx=_w(s, 0).end())
  File "/usr/local/python3/lib/python3.7/json/decoder.py", line 355, in raw_decode
    raise JSONDecodeError("Expecting value", s, err.value) from None
json.decoder.JSONDecodeError: Expecting value: line 1 column 1 (char 0)
INFO:root:Socket served at time: Fri Oct 25 18:29:52 2019 with: ('58.213.153.13', 51205)
INFO:root:successfully connected ...
ERROR:tornado.application:Exception in callback functools.partial(<function TCPServer._handle_connection.<locals>.<lambda> at 0x7fc51a8889e0>, <Future finished exception=UnicodeDecodeError('utf-8', b'\x16\x03\x00\x00S\x01\x00\x00O\x03\x00?G\xd7\xf7\xba,\xee\xea\xb2`~\xf3\x00\xfd\x82{\xb9\xd5\x96\xc8w\x9b\xe6\xc4\xdb<=\xdbo\xef\x10n\x00\x00(\x00\x16\x00\x13\x00\n\x00f\x00\x05\x00\x04\x00e\x00d\x00c\x00b\x00a\x00`\x00\x15\x00\x12\x00\t\x00\x14\x00\x11\x00\x08\x00\x06\x00\x03\x01\x00', 13, 14, 'invalid continuation byte')>)
Traceback (most recent call last):
  File "/usr/local/python3/lib/python3.7/site-packages/tornado/ioloop.py", line 743, in _run_callback
    ret = callback()
  File "/usr/local/python3/lib/python3.7/site-packages/tornado/tcpserver.py", line 327, in <lambda>
    gen.convert_yielded(future), lambda f: f.result()
  File "/usr/local/python3/lib/python3.7/site-packages/tornado/gen.py", line 748, in run
    yielded = self.gen.send(value)
  File "/home/Chunar/codes/Monitor_pi/motor_factory/fetch_data_server/socket_server.py", line 36, in handle_stream
    data_dict = json.loads(data.decode())
UnicodeDecodeError: 'utf-8' codec can't decode byte 0xd7 in position 13: invalid continuation byte
INFO:root:Socket served at time: Fri Oct 25 18:29:57 2019 with: ('58.213.153.13', 51237)
INFO:root:successfully connected ...
ERROR:tornado.application:Exception in callback functools.partial(<function TCPServer._handle_connection.<locals>.<lambda> at 0x7fc51a888e60>, <Future finished exception=UnicodeDecodeError('utf-8', b'\x16\x03\x00\x00i\x01\x00\x00e\x03\x03U\x1c\xa7\xe4random1random2random3random4\x00\x00\x0c\x00/\x00\n\x00\x13\x009\x00\x04\x00\xff\x01\x00\x000\x00\r\x00,\x00*\x00\x01\x00\x03\x00\x02\x06\x01\x06\x03\x06\x02\x02\x01\x02\x03\x02\x02\x03\x01\x03\x03\x03\x02\x04\x01\x04\x03\x04\x02\x01\x01\x01\x03\x01\x02\x05\x01\x05\x03\x05\x02', 13, 14, 'invalid start byte')>)
Traceback (most recent call last):
  File "/usr/local/python3/lib/python3.7/site-packages/tornado/ioloop.py", line 743, in _run_callback
    ret = callback()
  File "/usr/local/python3/lib/python3.7/site-packages/tornado/tcpserver.py", line 327, in <lambda>
    gen.convert_yielded(future), lambda f: f.result()
  File "/usr/local/python3/lib/python3.7/site-packages/tornado/gen.py", line 748, in run
    yielded = self.gen.send(value)
  File "/home/Chunar/codes/Monitor_pi/motor_factory/fetch_data_server/socket_server.py", line 36, in handle_stream
    data_dict = json.loads(data.decode())
UnicodeDecodeError: 'utf-8' codec can't decode byte 0xa7 in position 13: invalid start byte
INFO:root:Socket served at time: Fri Oct 25 18:30:02 2019 with: ('58.213.153.13', 51281)
INFO:root:successfully connected ...
ERROR:tornado.application:Exception in callback functools.partial(<function TCPServer._handle_connection.<locals>.<lambda> at 0x7fc51a888d40>, <Future finished exception=UnicodeDecodeError('utf-8', b'\x00\x00\x00qj\x81n0\x81k\xa1\x03\x02\x01\x05\xa2\x03\x02\x01\n\xa4\x81^0\\\xa0\x07\x03\x05\x00P\x80\x00\x10\xa2\x04\x1b\x02NM\xa3\x170\x15\xa0\x03\x02\x01\x00\xa1\x0e0\x0c\x1b\x06krbtgt\x1b\x02NM\xa5\x11\x18\x0f19700101000000Z\xa7\x06\x02\x04\x1f\x1e\xb9\xd9\xa8\x170\x15\x02\x01\x12\x02\x01\x11\x02\x01\x10\x02\x01\x17\x02\x01\x01\x02\x01\x03\x02\x01\x02', 5, 6, 'invalid start byte')>)
Traceback (most recent call last):
  File "/usr/local/python3/lib/python3.7/site-packages/tornado/ioloop.py", line 743, in _run_callback
    ret = callback()
  File "/usr/local/python3/lib/python3.7/site-packages/tornado/tcpserver.py", line 327, in <lambda>
    gen.convert_yielded(future), lambda f: f.result()
  File "/usr/local/python3/lib/python3.7/site-packages/tornado/gen.py", line 748, in run
    yielded = self.gen.send(value)
  File "/home/Chunar/codes/Monitor_pi/motor_factory/fetch_data_server/socket_server.py", line 36, in handle_stream
    data_dict = json.loads(data.decode())
UnicodeDecodeError: 'utf-8' codec can't decode byte 0x81 in position 5: invalid start byte
INFO:root:Socket served at time: Fri Oct 25 18:30:07 2019 with: ('58.213.153.13', 51327)
INFO:root:successfully connected ...
ERROR:tornado.application:Exception in callback functools.partial(<function TCPServer._handle_connection.<locals>.<lambda> at 0x7fc51a89b320>, <Future finished exception=UnicodeDecodeError('utf-8', b'\x00\x00\x00\xa4\xffSMBr\x00\x00\x00\x00\x08\x01@\x00\x00\x00\x00\x00\x00\x00\x00\x00\x00\x00\x00\x00\x00@\x06\x00\x00\x01\x00\x00\x81\x00\x02PC NETWORK PROGRAM 1.0\x00\x02MICROSOFT NETWORKS 1.03\x00\x02MICROSOFT NETWORKS 3.0\x00\x02LANMAN1.0\x00\x02LM1.2X002\x00\x02Samba\x00\x02NT LANMAN 1.0\x00\x02NT LM 0.12\x00', 3, 4, 'invalid start byte')>)
Traceback (most recent call last):
  File "/usr/local/python3/lib/python3.7/site-packages/tornado/ioloop.py", line 743, in _run_callback
    ret = callback()
  File "/usr/local/python3/lib/python3.7/site-packages/tornado/tcpserver.py", line 327, in <lambda>
    gen.convert_yielded(future), lambda f: f.result()
  File "/usr/local/python3/lib/python3.7/site-packages/tornado/gen.py", line 748, in run
    yielded = self.gen.send(value)
  File "/home/Chunar/codes/Monitor_pi/motor_factory/fetch_data_server/socket_server.py", line 36, in handle_stream
    data_dict = json.loads(data.decode())
UnicodeDecodeError: 'utf-8' codec can't decode byte 0xa4 in position 3: invalid start byte
INFO:root:Socket served at time: Fri Oct 25 18:30:12 2019 with: ('58.213.153.13', 51381)
INFO:root:successfully connected ...
ERROR:tornado.application:Exception in callback functools.partial(<function TCPServer._handle_connection.<locals>.<lambda> at 0x7fc51a89b560>, <Future finished exception=JSONDecodeError('Expecting value: line 1 column 1 (char 0)')>)
Traceback (most recent call last):
  File "/usr/local/python3/lib/python3.7/site-packages/tornado/ioloop.py", line 743, in _run_callback
    ret = callback()
  File "/usr/local/python3/lib/python3.7/site-packages/tornado/tcpserver.py", line 327, in <lambda>
    gen.convert_yielded(future), lambda f: f.result()
  File "/usr/local/python3/lib/python3.7/site-packages/tornado/gen.py", line 748, in run
    yielded = self.gen.send(value)
  File "/home/Chunar/codes/Monitor_pi/motor_factory/fetch_data_server/socket_server.py", line 36, in handle_stream
    data_dict = json.loads(data.decode())
  File "/usr/local/python3/lib/python3.7/json/__init__.py", line 348, in loads
    return _default_decoder.decode(s)
  File "/usr/local/python3/lib/python3.7/json/decoder.py", line 337, in decode
    obj, end = self.raw_decode(s, idx=_w(s, 0).end())
  File "/usr/local/python3/lib/python3.7/json/decoder.py", line 355, in raw_decode
    raise JSONDecodeError("Expecting value", s, err.value) from None
json.decoder.JSONDecodeError: Expecting value: line 1 column 1 (char 0)
INFO:root:Socket served at time: Fri Oct 25 18:30:18 2019 with: ('58.213.153.13', 51424)
INFO:root:successfully connected ...
ERROR:tornado.application:Exception in callback functools.partial(<function TCPServer._handle_connection.<locals>.<lambda> at 0x7fc51a89b710>, <Future finished exception=JSONDecodeError('Expecting value: line 1 column 1 (char 0)')>)
Traceback (most recent call last):
  File "/usr/local/python3/lib/python3.7/site-packages/tornado/ioloop.py", line 743, in _run_callback
    ret = callback()
  File "/usr/local/python3/lib/python3.7/site-packages/tornado/tcpserver.py", line 327, in <lambda>
    gen.convert_yielded(future), lambda f: f.result()
  File "/usr/local/python3/lib/python3.7/site-packages/tornado/gen.py", line 748, in run
    yielded = self.gen.send(value)
  File "/home/Chunar/codes/Monitor_pi/motor_factory/fetch_data_server/socket_server.py", line 36, in handle_stream
    data_dict = json.loads(data.decode())
  File "/usr/local/python3/lib/python3.7/json/__init__.py", line 348, in loads
    return _default_decoder.decode(s)
  File "/usr/local/python3/lib/python3.7/json/decoder.py", line 337, in decode
    obj, end = self.raw_decode(s, idx=_w(s, 0).end())
  File "/usr/local/python3/lib/python3.7/json/decoder.py", line 355, in raw_decode
    raise JSONDecodeError("Expecting value", s, err.value) from None
json.decoder.JSONDecodeError: Expecting value: line 1 column 1 (char 0)
INFO:root:Socket served at time: Fri Oct 25 18:30:23 2019 with: ('58.213.153.13', 51454)
INFO:root:successfully connected ...
ERROR:tornado.application:Exception in callback functools.partial(<function TCPServer._handle_connection.<locals>.<lambda> at 0x7fc51a89b8c0>, <Future finished exception=JSONDecodeError('Expecting value: line 1 column 1 (char 0)')>)
Traceback (most recent call last):
  File "/usr/local/python3/lib/python3.7/site-packages/tornado/ioloop.py", line 743, in _run_callback
    ret = callback()
  File "/usr/local/python3/lib/python3.7/site-packages/tornado/tcpserver.py", line 327, in <lambda>
    gen.convert_yielded(future), lambda f: f.result()
  File "/usr/local/python3/lib/python3.7/site-packages/tornado/gen.py", line 748, in run
    yielded = self.gen.send(value)
  File "/home/Chunar/codes/Monitor_pi/motor_factory/fetch_data_server/socket_server.py", line 36, in handle_stream
    data_dict = json.loads(data.decode())
  File "/usr/local/python3/lib/python3.7/json/__init__.py", line 348, in loads
    return _default_decoder.decode(s)
  File "/usr/local/python3/lib/python3.7/json/decoder.py", line 337, in decode
    obj, end = self.raw_decode(s, idx=_w(s, 0).end())
  File "/usr/local/python3/lib/python3.7/json/decoder.py", line 355, in raw_decode
    raise JSONDecodeError("Expecting value", s, err.value) from None
json.decoder.JSONDecodeError: Expecting value: line 1 column 1 (char 0)
INFO:root:Socket served at time: Fri Oct 25 18:30:28 2019 with: ('58.213.153.13', 51505)
INFO:root:successfully connected ...
ERROR:tornado.application:Exception in callback functools.partial(<function TCPServer._handle_connection.<locals>.<lambda> at 0x7fc51a89ba70>, <Future finished exception=UnicodeDecodeError('utf-8', b'0\x84\x00\x00\x00-\x02\x01\x07c\x84\x00\x00\x00$\x04\x00\n\x01\x00\n\x01\x00\x02\x01\x00\x02\x01d\x01\x01\x00\x87\x0bobjectClass0\x84\x00\x00\x00\x00', 1, 2, 'invalid start byte')>)
Traceback (most recent call last):
  File "/usr/local/python3/lib/python3.7/site-packages/tornado/ioloop.py", line 743, in _run_callback
    ret = callback()
  File "/usr/local/python3/lib/python3.7/site-packages/tornado/tcpserver.py", line 327, in <lambda>
    gen.convert_yielded(future), lambda f: f.result()
  File "/usr/local/python3/lib/python3.7/site-packages/tornado/gen.py", line 748, in run
    yielded = self.gen.send(value)
  File "/home/Chunar/codes/Monitor_pi/motor_factory/fetch_data_server/socket_server.py", line 36, in handle_stream
    data_dict = json.loads(data.decode())
UnicodeDecodeError: 'utf-8' codec can't decode byte 0x84 in position 1: invalid start byte
INFO:root:Socket served at time: Fri Oct 25 18:30:33 2019 with: ('58.213.153.13', 51563)
INFO:root:successfully connected ...
ERROR:tornado.application:Exception in callback functools.partial(<function TCPServer._handle_connection.<locals>.<lambda> at 0x7fc51a89bcb0>, <Future finished exception=UnicodeDecodeError('utf-8', b'0\x0c\x02\x01\x01`\x07\x02\x01\x02\x04\x00\x80\x00', 12, 13, 'invalid start byte')>)
Traceback (most recent call last):
  File "/usr/local/python3/lib/python3.7/site-packages/tornado/ioloop.py", line 743, in _run_callback
    ret = callback()
  File "/usr/local/python3/lib/python3.7/site-packages/tornado/tcpserver.py", line 327, in <lambda>
    gen.convert_yielded(future), lambda f: f.result()
  File "/usr/local/python3/lib/python3.7/site-packages/tornado/gen.py", line 748, in run
    yielded = self.gen.send(value)
  File "/home/Chunar/codes/Monitor_pi/motor_factory/fetch_data_server/socket_server.py", line 36, in handle_stream
    data_dict = json.loads(data.decode())
UnicodeDecodeError: 'utf-8' codec can't decode byte 0x80 in position 12: invalid start byte
INFO:root:Socket served at time: Fri Oct 25 18:30:38 2019 with: ('58.213.153.13', 51648)
INFO:root:successfully connected ...
ERROR:tornado.application:Exception in callback functools.partial(<function TCPServer._handle_connection.<locals>.<lambda> at 0x7fc51a89bef0>, <Future finished exception=JSONDecodeError('Expecting value: line 1 column 1 (char 0)')>)
Traceback (most recent call last):
  File "/usr/local/python3/lib/python3.7/site-packages/tornado/ioloop.py", line 743, in _run_callback
    ret = callback()
  File "/usr/local/python3/lib/python3.7/site-packages/tornado/tcpserver.py", line 327, in <lambda>
    gen.convert_yielded(future), lambda f: f.result()
  File "/usr/local/python3/lib/python3.7/site-packages/tornado/gen.py", line 748, in run
    yielded = self.gen.send(value)
  File "/home/Chunar/codes/Monitor_pi/motor_factory/fetch_data_server/socket_server.py", line 36, in handle_stream
    data_dict = json.loads(data.decode())
  File "/usr/local/python3/lib/python3.7/json/__init__.py", line 348, in loads
    return _default_decoder.decode(s)
  File "/usr/local/python3/lib/python3.7/json/decoder.py", line 337, in decode
    obj, end = self.raw_decode(s, idx=_w(s, 0).end())
  File "/usr/local/python3/lib/python3.7/json/decoder.py", line 355, in raw_decode
    raise JSONDecodeError("Expecting value", s, err.value) from None
json.decoder.JSONDecodeError: Expecting value: line 1 column 1 (char 0)
INFO:root:Socket served at time: Fri Oct 25 18:30:45 2019 with: ('58.213.153.13', 51731)
INFO:root:successfully connected ...
ERROR:tornado.application:Exception in callback functools.partial(<function TCPServer._handle_connection.<locals>.<lambda> at 0x7fc51a8ae0e0>, <Future finished exception=JSONDecodeError('Expecting value: line 1 column 1 (char 0)')>)
Traceback (most recent call last):
  File "/usr/local/python3/lib/python3.7/site-packages/tornado/ioloop.py", line 743, in _run_callback
    ret = callback()
  File "/usr/local/python3/lib/python3.7/site-packages/tornado/tcpserver.py", line 327, in <lambda>
    gen.convert_yielded(future), lambda f: f.result()
  File "/usr/local/python3/lib/python3.7/site-packages/tornado/gen.py", line 748, in run
    yielded = self.gen.send(value)
  File "/home/Chunar/codes/Monitor_pi/motor_factory/fetch_data_server/socket_server.py", line 36, in handle_stream
    data_dict = json.loads(data.decode())
  File "/usr/local/python3/lib/python3.7/json/__init__.py", line 348, in loads
    return _default_decoder.decode(s)
  File "/usr/local/python3/lib/python3.7/json/decoder.py", line 337, in decode
    obj, end = self.raw_decode(s, idx=_w(s, 0).end())
  File "/usr/local/python3/lib/python3.7/json/decoder.py", line 355, in raw_decode
    raise JSONDecodeError("Expecting value", s, err.value) from None
json.decoder.JSONDecodeError: Expecting value: line 1 column 1 (char 0)
INFO:root:Socket served at time: Fri Oct 25 18:30:50 2019 with: ('58.213.153.13', 51771)
INFO:root:successfully connected ...
ERROR:tornado.application:Exception in callback functools.partial(<function TCPServer._handle_connection.<locals>.<lambda> at 0x7fc51a89bef0>, <Future finished exception=UnicodeDecodeError('utf-8', b'\x03\x00\x00\x0b\x06\xe0\x00\x00\x00\x00\x00', 5, 6, 'invalid continuation byte')>)
Traceback (most recent call last):
  File "/usr/local/python3/lib/python3.7/site-packages/tornado/ioloop.py", line 743, in _run_callback
    ret = callback()
  File "/usr/local/python3/lib/python3.7/site-packages/tornado/tcpserver.py", line 327, in <lambda>
    gen.convert_yielded(future), lambda f: f.result()
  File "/usr/local/python3/lib/python3.7/site-packages/tornado/gen.py", line 748, in run
    yielded = self.gen.send(value)
  File "/home/Chunar/codes/Monitor_pi/motor_factory/fetch_data_server/socket_server.py", line 36, in handle_stream
    data_dict = json.loads(data.decode())
UnicodeDecodeError: 'utf-8' codec can't decode byte 0xe0 in position 5: invalid continuation byte
INFO:root:Socket served at time: Fri Oct 25 18:30:55 2019 with: ('58.213.153.13', 51831)
INFO:root:successfully connected ...
ERROR:tornado.application:Exception in callback functools.partial(<function TCPServer._handle_connection.<locals>.<lambda> at 0x7fc51a89bb90>, <Future finished exception=UnicodeDecodeError('utf-8', b'DmdT\x00\x00\x00\x17\x00\x00\x00\x01\x00\x00\x00\x00\x11\x11\x00\xff\x01\xff\x13', 19, 20, 'invalid start byte')>)
Traceback (most recent call last):
  File "/usr/local/python3/lib/python3.7/site-packages/tornado/ioloop.py", line 743, in _run_callback
    ret = callback()
  File "/usr/local/python3/lib/python3.7/site-packages/tornado/tcpserver.py", line 327, in <lambda>
    gen.convert_yielded(future), lambda f: f.result()
  File "/usr/local/python3/lib/python3.7/site-packages/tornado/gen.py", line 748, in run
    yielded = self.gen.send(value)
  File "/home/Chunar/codes/Monitor_pi/motor_factory/fetch_data_server/socket_server.py", line 36, in handle_stream
    data_dict = json.loads(data.decode())
UnicodeDecodeError: 'utf-8' codec can't decode byte 0xff in position 19: invalid start byte
INFO:root:Socket served at time: Fri Oct 25 18:31:00 2019 with: ('58.213.153.13', 51910)
INFO:root:successfully connected ...
ERROR:tornado.application:Exception in callback functools.partial(<function TCPServer._handle_connection.<locals>.<lambda> at 0x7fc51a89b950>, <Future finished exception=JSONDecodeError('Expecting value: line 1 column 1 (char 0)')>)
Traceback (most recent call last):
  File "/usr/local/python3/lib/python3.7/site-packages/tornado/ioloop.py", line 743, in _run_callback
    ret = callback()
  File "/usr/local/python3/lib/python3.7/site-packages/tornado/tcpserver.py", line 327, in <lambda>
    gen.convert_yielded(future), lambda f: f.result()
  File "/usr/local/python3/lib/python3.7/site-packages/tornado/gen.py", line 748, in run
    yielded = self.gen.send(value)
  File "/home/Chunar/codes/Monitor_pi/motor_factory/fetch_data_server/socket_server.py", line 36, in handle_stream
    data_dict = json.loads(data.decode())
  File "/usr/local/python3/lib/python3.7/json/__init__.py", line 348, in loads
    return _default_decoder.decode(s)
  File "/usr/local/python3/lib/python3.7/json/decoder.py", line 337, in decode
    obj, end = self.raw_decode(s, idx=_w(s, 0).end())
  File "/usr/local/python3/lib/python3.7/json/decoder.py", line 355, in raw_decode
    raise JSONDecodeError("Expecting value", s, err.value) from None
json.decoder.JSONDecodeError: Expecting value: line 1 column 1 (char 0)
INFO:root:Socket served at time: Fri Oct 25 18:31:05 2019 with: ('58.213.153.13', 51946)
INFO:root:successfully connected ...
ERROR:tornado.application:Exception in callback functools.partial(<function TCPServer._handle_connection.<locals>.<lambda> at 0x7fc51a89b8c0>, <Future finished exception=JSONDecodeError('Expecting value: line 1 column 1 (char 0)')>)
Traceback (most recent call last):
  File "/usr/local/python3/lib/python3.7/site-packages/tornado/ioloop.py", line 743, in _run_callback
    ret = callback()
  File "/usr/local/python3/lib/python3.7/site-packages/tornado/tcpserver.py", line 327, in <lambda>
    gen.convert_yielded(future), lambda f: f.result()
  File "/usr/local/python3/lib/python3.7/site-packages/tornado/gen.py", line 748, in run
    yielded = self.gen.send(value)
  File "/home/Chunar/codes/Monitor_pi/motor_factory/fetch_data_server/socket_server.py", line 36, in handle_stream
    data_dict = json.loads(data.decode())
  File "/usr/local/python3/lib/python3.7/json/__init__.py", line 348, in loads
    return _default_decoder.decode(s)
  File "/usr/local/python3/lib/python3.7/json/decoder.py", line 337, in decode
    obj, end = self.raw_decode(s, idx=_w(s, 0).end())
  File "/usr/local/python3/lib/python3.7/json/decoder.py", line 355, in raw_decode
    raise JSONDecodeError("Expecting value", s, err.value) from None
json.decoder.JSONDecodeError: Expecting value: line 1 column 1 (char 0)
INFO:root:Socket served at time: Fri Oct 25 18:31:10 2019 with: ('58.213.153.13', 51993)
INFO:root:successfully connected ...
ERROR:tornado.application:Exception in callback functools.partial(<function TCPServer._handle_connection.<locals>.<lambda> at 0x7fc51a89b710>, <Future finished exception=UnicodeDecodeError('utf-8', b'\x01\x00\x00\xfd\xce\xfa\x0b\xb0\xa0\x00\x00\x00MMS\x14\x00\x00\x00\x00\x00\x00\x00\x00\x00\x00\x00\x00\x00\x00\x00\x12\x00\x00\x00\x01\x00\x03\x00\xf0\xf0\xf0\xf0\x0b\x00\x04\x00\x1c\x00\x03\x00N\x00S\x00P\x00l\x00a\x00y\x00e\x00r\x00/\x009\x00.\x000\x00.\x000\x00.\x002\x009\x008\x000\x00;\x00 \x00{\x000\x000\x000\x000\x00A\x00A\x000\x000\x00-\x000\x00A\x000\x000\x00-\x000\x000\x00a\x000\x00-\x00A\x00A\x000\x00A\x00-\x000\x000\x000\x000\x00A\x000\x00A\x00A\x000\x00A\x00A\x000\x00}\x00\x00\x00\xe0m\xdf_', 3, 4, 'invalid start byte')>)
Traceback (most recent call last):
  File "/usr/local/python3/lib/python3.7/site-packages/tornado/ioloop.py", line 743, in _run_callback
    ret = callback()
  File "/usr/local/python3/lib/python3.7/site-packages/tornado/tcpserver.py", line 327, in <lambda>
    gen.convert_yielded(future), lambda f: f.result()
  File "/usr/local/python3/lib/python3.7/site-packages/tornado/gen.py", line 748, in run
    yielded = self.gen.send(value)
  File "/home/Chunar/codes/Monitor_pi/motor_factory/fetch_data_server/socket_server.py", line 36, in handle_stream
    data_dict = json.loads(data.decode())
UnicodeDecodeError: 'utf-8' codec can't decode byte 0xfd in position 3: invalid start byte
INFO:root:Socket served at time: Fri Oct 25 18:31:15 2019 with: ('58.213.153.13', 52034)
INFO:root:successfully connected ...
ERROR:tornado.application:Exception in callback functools.partial(<function TCPServer._handle_connection.<locals>.<lambda> at 0x7fc51a89b290>, <Future finished exception=UnicodeDecodeError('utf-8', b'\x00Z\x00\x00\x01\x00\x00\x00\x016\x01,\x00\x00\x08\x00\x7f\xff\x7f\x08\x00\x00\x00\x01\x00 \x00:\x00\x00\x00\x00\x00\x00\x00\x00\x00\x00\x00\x00\x00\x00\x00\x004\xe6\x00\x00\x00\x01\x00\x00\x00\x00\x00\x00\x00\x00(CONNECT_DATA=(COMMAND=version))', 17, 18, 'invalid start byte')>)
Traceback (most recent call last):
  File "/usr/local/python3/lib/python3.7/site-packages/tornado/ioloop.py", line 743, in _run_callback
    ret = callback()
  File "/usr/local/python3/lib/python3.7/site-packages/tornado/tcpserver.py", line 327, in <lambda>
    gen.convert_yielded(future), lambda f: f.result()
  File "/usr/local/python3/lib/python3.7/site-packages/tornado/gen.py", line 748, in run
    yielded = self.gen.send(value)
  File "/home/Chunar/codes/Monitor_pi/motor_factory/fetch_data_server/socket_server.py", line 36, in handle_stream
    data_dict = json.loads(data.decode())
UnicodeDecodeError: 'utf-8' codec can't decode byte 0xff in position 17: invalid start byte
INFO:root:Socket served at time: Fri Oct 25 18:31:21 2019 with: ('58.213.153.13', 52076)
INFO:root:successfully connected ...
ERROR:tornado.application:Exception in callback functools.partial(<function TCPServer._handle_connection.<locals>.<lambda> at 0x7fc51a89b170>, <Future finished exception=UnicodeDecodeError('utf-8', b'\x12\x01\x004\x00\x00\x00\x00\x00\x00\x15\x00\x06\x01\x00\x1b\x00\x01\x02\x00\x1c\x00\x0c\x03\x00(\x00\x04\xff\x08\x00\x01U\x00\x00\x00MSSQLServer\x00H\x0f\x00\x00', 28, 29, 'invalid start byte')>)
Traceback (most recent call last):
  File "/usr/local/python3/lib/python3.7/site-packages/tornado/ioloop.py", line 743, in _run_callback
    ret = callback()
  File "/usr/local/python3/lib/python3.7/site-packages/tornado/tcpserver.py", line 327, in <lambda>
    gen.convert_yielded(future), lambda f: f.result()
  File "/usr/local/python3/lib/python3.7/site-packages/tornado/gen.py", line 748, in run
    yielded = self.gen.send(value)
  File "/home/Chunar/codes/Monitor_pi/motor_factory/fetch_data_server/socket_server.py", line 36, in handle_stream
    data_dict = json.loads(data.decode())
UnicodeDecodeError: 'utf-8' codec can't decode byte 0xff in position 28: invalid start byte
INFO:root:Socket served at time: Fri Oct 25 18:31:26 2019 with: ('58.213.153.13', 52106)
INFO:root:successfully connected ...
ERROR:tornado.application:Exception in callback functools.partial(<function TCPServer._handle_connection.<locals>.<lambda> at 0x7fc51a8cb0e0>, <Future finished exception=JSONDecodeError('Expecting value: line 1 column 1 (char 0)')>)
Traceback (most recent call last):
  File "/usr/local/python3/lib/python3.7/site-packages/tornado/ioloop.py", line 743, in _run_callback
    ret = callback()
  File "/usr/local/python3/lib/python3.7/site-packages/tornado/tcpserver.py", line 327, in <lambda>
    gen.convert_yielded(future), lambda f: f.result()
  File "/usr/local/python3/lib/python3.7/site-packages/tornado/gen.py", line 748, in run
    yielded = self.gen.send(value)
  File "/home/Chunar/codes/Monitor_pi/motor_factory/fetch_data_server/socket_server.py", line 36, in handle_stream
    data_dict = json.loads(data.decode())
  File "/usr/local/python3/lib/python3.7/json/__init__.py", line 348, in loads
    return _default_decoder.decode(s)
  File "/usr/local/python3/lib/python3.7/json/decoder.py", line 337, in decode
    obj, end = self.raw_decode(s, idx=_w(s, 0).end())
  File "/usr/local/python3/lib/python3.7/json/decoder.py", line 355, in raw_decode
    raise JSONDecodeError("Expecting value", s, err.value) from None
json.decoder.JSONDecodeError: Expecting value: line 1 column 1 (char 0)
INFO:root:Socket served at time: Fri Oct 25 18:31:31 2019 with: ('58.213.153.13', 52152)
INFO:root:successfully connected ...
ERROR:tornado.application:Exception in callback functools.partial(<function TCPServer._handle_connection.<locals>.<lambda> at 0x7fc51ab53ef0>, <Future finished exception=JSONDecodeError('Expecting value: line 1 column 1 (char 0)')>)
Traceback (most recent call last):
  File "/usr/local/python3/lib/python3.7/site-packages/tornado/ioloop.py", line 743, in _run_callback
    ret = callback()
  File "/usr/local/python3/lib/python3.7/site-packages/tornado/tcpserver.py", line 327, in <lambda>
    gen.convert_yielded(future), lambda f: f.result()
  File "/usr/local/python3/lib/python3.7/site-packages/tornado/gen.py", line 748, in run
    yielded = self.gen.send(value)
  File "/home/Chunar/codes/Monitor_pi/motor_factory/fetch_data_server/socket_server.py", line 36, in handle_stream
    data_dict = json.loads(data.decode())
  File "/usr/local/python3/lib/python3.7/json/__init__.py", line 348, in loads
    return _default_decoder.decode(s)
  File "/usr/local/python3/lib/python3.7/json/decoder.py", line 337, in decode
    obj, end = self.raw_decode(s, idx=_w(s, 0).end())
  File "/usr/local/python3/lib/python3.7/json/decoder.py", line 355, in raw_decode
    raise JSONDecodeError("Expecting value", s, err.value) from None
json.decoder.JSONDecodeError: Expecting value: line 1 column 1 (char 0)
INFO:root:Socket served at time: Fri Oct 25 18:31:40 2019 with: ('58.213.153.13', 52278)
INFO:root:successfully connected ...
INFO:root:Socket served at time: Fri Oct 25 18:31:40 2019 with: ('58.213.153.13', 52273)
INFO:root:successfully connected ...
ERROR:tornado.application:Exception in callback functools.partial(<function TCPServer._handle_connection.<locals>.<lambda> at 0x7fc51a8883b0>, <Future finished exception=JSONDecodeError('Expecting value: line 1 column 1 (char 0)')>)
Traceback (most recent call last):
  File "/usr/local/python3/lib/python3.7/site-packages/tornado/ioloop.py", line 743, in _run_callback
    ret = callback()
  File "/usr/local/python3/lib/python3.7/site-packages/tornado/tcpserver.py", line 327, in <lambda>
    gen.convert_yielded(future), lambda f: f.result()
  File "/usr/local/python3/lib/python3.7/site-packages/tornado/gen.py", line 748, in run
    yielded = self.gen.send(value)
  File "/home/Chunar/codes/Monitor_pi/motor_factory/fetch_data_server/socket_server.py", line 36, in handle_stream
    data_dict = json.loads(data.decode())
  File "/usr/local/python3/lib/python3.7/json/__init__.py", line 348, in loads
    return _default_decoder.decode(s)
  File "/usr/local/python3/lib/python3.7/json/decoder.py", line 337, in decode
    obj, end = self.raw_decode(s, idx=_w(s, 0).end())
  File "/usr/local/python3/lib/python3.7/json/decoder.py", line 355, in raw_decode
    raise JSONDecodeError("Expecting value", s, err.value) from None
json.decoder.JSONDecodeError: Expecting value: line 1 column 1 (char 0)
INFO:root:Server finished
INFO:root:*************************
INFO:root:Socket served at time: Fri Oct 25 18:31:50 2019 with: ('58.213.153.13', 742)
INFO:root:successfully connected ...
ERROR:tornado.application:Exception in callback functools.partial(<function TCPServer._handle_connection.<locals>.<lambda> at 0x7fc51a8889e0>, <Future finished exception=UnicodeDecodeError('utf-8', b'\x80\x00\x00(G\x07<\xd2\x00\x00\x00\x00\x00\x00\x00\x02\x00\x01\x86\xa0\x00\x00\x00\x02\x00\x00\x00\x00\x00\x00\x00\x00\x00\x00\x00\x00\x00\x00\x00\x00\x00\x00\x00\x00', 0, 1, 'invalid start byte')>)
Traceback (most recent call last):
  File "/usr/local/python3/lib/python3.7/site-packages/tornado/ioloop.py", line 743, in _run_callback
    ret = callback()
  File "/usr/local/python3/lib/python3.7/site-packages/tornado/tcpserver.py", line 327, in <lambda>
    gen.convert_yielded(future), lambda f: f.result()
  File "/usr/local/python3/lib/python3.7/site-packages/tornado/gen.py", line 748, in run
    yielded = self.gen.send(value)
  File "/home/Chunar/codes/Monitor_pi/motor_factory/fetch_data_server/socket_server.py", line 36, in handle_stream
    data_dict = json.loads(data.decode())
UnicodeDecodeError: 'utf-8' codec can't decode byte 0x80 in position 0: invalid start byte
DEBUG:asyncio:Using selector: EpollSelector
DEBUG:asyncio:Using selector: EpollSelector
DEBUG:asyncio:Using selector: EpollSelector
INFO:root:Socket served at time: Fri Nov  1 11:15:22 2019 with: ('58.213.153.13', 56277)
INFO:root:successfully connected ...
ERROR:tornado.application:Exception in callback functools.partial(<function TCPServer._handle_connection.<locals>.<lambda> at 0x7fc2a218d170>, <Future finished exception=JSONDecodeError('Expecting value: line 3 column 1 (char 4)')>)
Traceback (most recent call last):
  File "/usr/local/python3/lib/python3.7/site-packages/tornado/ioloop.py", line 743, in _run_callback
    ret = callback()
  File "/usr/local/python3/lib/python3.7/site-packages/tornado/tcpserver.py", line 327, in <lambda>
    gen.convert_yielded(future), lambda f: f.result()
  File "/usr/local/python3/lib/python3.7/site-packages/tornado/gen.py", line 748, in run
    yielded = self.gen.send(value)
  File "/home/Chunar/codes/Monitor_pi/motor_factory/fetch_data_server/socket_server.py", line 36, in handle_stream
    data_dict = json.loads(data.decode())
  File "/usr/local/python3/lib/python3.7/json/__init__.py", line 348, in loads
    return _default_decoder.decode(s)
  File "/usr/local/python3/lib/python3.7/json/decoder.py", line 337, in decode
    obj, end = self.raw_decode(s, idx=_w(s, 0).end())
  File "/usr/local/python3/lib/python3.7/json/decoder.py", line 355, in raw_decode
    raise JSONDecodeError("Expecting value", s, err.value) from None
json.decoder.JSONDecodeError: Expecting value: line 3 column 1 (char 4)
INFO:root:Socket served at time: Fri Nov  1 11:15:33 2019 with: ('58.213.153.13', 56395)
INFO:root:successfully connected ...
ERROR:tornado.application:Exception in callback functools.partial(<function TCPServer._handle_connection.<locals>.<lambda> at 0x7fc2a21c8320>, <Future finished exception=JSONDecodeError('Expecting value: line 1 column 1 (char 0)')>)
Traceback (most recent call last):
  File "/usr/local/python3/lib/python3.7/site-packages/tornado/ioloop.py", line 743, in _run_callback
    ret = callback()
  File "/usr/local/python3/lib/python3.7/site-packages/tornado/tcpserver.py", line 327, in <lambda>
    gen.convert_yielded(future), lambda f: f.result()
  File "/usr/local/python3/lib/python3.7/site-packages/tornado/gen.py", line 748, in run
    yielded = self.gen.send(value)
  File "/home/Chunar/codes/Monitor_pi/motor_factory/fetch_data_server/socket_server.py", line 36, in handle_stream
    data_dict = json.loads(data.decode())
  File "/usr/local/python3/lib/python3.7/json/__init__.py", line 348, in loads
    return _default_decoder.decode(s)
  File "/usr/local/python3/lib/python3.7/json/decoder.py", line 337, in decode
    obj, end = self.raw_decode(s, idx=_w(s, 0).end())
  File "/usr/local/python3/lib/python3.7/json/decoder.py", line 355, in raw_decode
    raise JSONDecodeError("Expecting value", s, err.value) from None
json.decoder.JSONDecodeError: Expecting value: line 1 column 1 (char 0)
INFO:root:Socket served at time: Fri Nov  1 11:15:39 2019 with: ('58.213.153.13', 56444)
INFO:root:successfully connected ...
ERROR:tornado.application:Exception in callback functools.partial(<function TCPServer._handle_connection.<locals>.<lambda> at 0x7fc2a21c84d0>, <Future finished exception=JSONDecodeError('Expecting value: line 1 column 1 (char 0)')>)
Traceback (most recent call last):
  File "/usr/local/python3/lib/python3.7/site-packages/tornado/ioloop.py", line 743, in _run_callback
    ret = callback()
  File "/usr/local/python3/lib/python3.7/site-packages/tornado/tcpserver.py", line 327, in <lambda>
    gen.convert_yielded(future), lambda f: f.result()
  File "/usr/local/python3/lib/python3.7/site-packages/tornado/gen.py", line 748, in run
    yielded = self.gen.send(value)
  File "/home/Chunar/codes/Monitor_pi/motor_factory/fetch_data_server/socket_server.py", line 36, in handle_stream
    data_dict = json.loads(data.decode())
  File "/usr/local/python3/lib/python3.7/json/__init__.py", line 348, in loads
    return _default_decoder.decode(s)
  File "/usr/local/python3/lib/python3.7/json/decoder.py", line 337, in decode
    obj, end = self.raw_decode(s, idx=_w(s, 0).end())
  File "/usr/local/python3/lib/python3.7/json/decoder.py", line 355, in raw_decode
    raise JSONDecodeError("Expecting value", s, err.value) from None
json.decoder.JSONDecodeError: Expecting value: line 1 column 1 (char 0)
INFO:root:Socket served at time: Fri Nov  1 11:15:44 2019 with: ('58.213.153.13', 56464)
INFO:root:successfully connected ...
ERROR:tornado.application:Exception in callback functools.partial(<function TCPServer._handle_connection.<locals>.<lambda> at 0x7fc2a21c8680>, <Future finished exception=JSONDecodeError('Expecting value: line 1 column 1 (char 0)')>)
Traceback (most recent call last):
  File "/usr/local/python3/lib/python3.7/site-packages/tornado/ioloop.py", line 743, in _run_callback
    ret = callback()
  File "/usr/local/python3/lib/python3.7/site-packages/tornado/tcpserver.py", line 327, in <lambda>
    gen.convert_yielded(future), lambda f: f.result()
  File "/usr/local/python3/lib/python3.7/site-packages/tornado/gen.py", line 748, in run
    yielded = self.gen.send(value)
  File "/home/Chunar/codes/Monitor_pi/motor_factory/fetch_data_server/socket_server.py", line 36, in handle_stream
    data_dict = json.loads(data.decode())
  File "/usr/local/python3/lib/python3.7/json/__init__.py", line 348, in loads
    return _default_decoder.decode(s)
  File "/usr/local/python3/lib/python3.7/json/decoder.py", line 337, in decode
    obj, end = self.raw_decode(s, idx=_w(s, 0).end())
  File "/usr/local/python3/lib/python3.7/json/decoder.py", line 355, in raw_decode
    raise JSONDecodeError("Expecting value", s, err.value) from None
json.decoder.JSONDecodeError: Expecting value: line 1 column 1 (char 0)
INFO:root:Socket served at time: Fri Nov  1 11:15:49 2019 with: ('58.213.153.13', 56489)
INFO:root:successfully connected ...
ERROR:tornado.application:Exception in callback functools.partial(<function TCPServer._handle_connection.<locals>.<lambda> at 0x7fc2a21c8830>, <Future finished exception=UnicodeDecodeError('utf-8', b'\x80\x00\x00(r\xfe\x1d\x13\x00\x00\x00\x00\x00\x00\x00\x02\x00\x01\x86\xa0\x00\x01\x97|\x00\x00\x00\x00\x00\x00\x00\x00\x00\x00\x00\x00\x00\x00\x00\x00\x00\x00\x00\x00', 0, 1, 'invalid start byte')>)
Traceback (most recent call last):
  File "/usr/local/python3/lib/python3.7/site-packages/tornado/ioloop.py", line 743, in _run_callback
    ret = callback()
  File "/usr/local/python3/lib/python3.7/site-packages/tornado/tcpserver.py", line 327, in <lambda>
    gen.convert_yielded(future), lambda f: f.result()
  File "/usr/local/python3/lib/python3.7/site-packages/tornado/gen.py", line 748, in run
    yielded = self.gen.send(value)
  File "/home/Chunar/codes/Monitor_pi/motor_factory/fetch_data_server/socket_server.py", line 36, in handle_stream
    data_dict = json.loads(data.decode())
UnicodeDecodeError: 'utf-8' codec can't decode byte 0x80 in position 0: invalid start byte
INFO:root:Socket served at time: Fri Nov  1 11:15:54 2019 with: ('58.213.153.13', 56492)
INFO:root:successfully connected ...
ERROR:tornado.application:Exception in callback functools.partial(<function TCPServer._handle_connection.<locals>.<lambda> at 0x7fc2a21c8a70>, <Future finished exception=JSONDecodeError('Expecting value: line 1 column 1 (char 0)')>)
Traceback (most recent call last):
  File "/usr/local/python3/lib/python3.7/site-packages/tornado/ioloop.py", line 743, in _run_callback
    ret = callback()
  File "/usr/local/python3/lib/python3.7/site-packages/tornado/tcpserver.py", line 327, in <lambda>
    gen.convert_yielded(future), lambda f: f.result()
  File "/usr/local/python3/lib/python3.7/site-packages/tornado/gen.py", line 748, in run
    yielded = self.gen.send(value)
  File "/home/Chunar/codes/Monitor_pi/motor_factory/fetch_data_server/socket_server.py", line 36, in handle_stream
    data_dict = json.loads(data.decode())
  File "/usr/local/python3/lib/python3.7/json/__init__.py", line 348, in loads
    return _default_decoder.decode(s)
  File "/usr/local/python3/lib/python3.7/json/decoder.py", line 337, in decode
    obj, end = self.raw_decode(s, idx=_w(s, 0).end())
  File "/usr/local/python3/lib/python3.7/json/decoder.py", line 355, in raw_decode
    raise JSONDecodeError("Expecting value", s, err.value) from None
json.decoder.JSONDecodeError: Expecting value: line 1 column 1 (char 0)
INFO:root:Socket served at time: Fri Nov  1 11:15:59 2019 with: ('58.213.153.13', 56500)
INFO:root:successfully connected ...
ERROR:tornado.application:Exception in callback functools.partial(<function TCPServer._handle_connection.<locals>.<lambda> at 0x7fc2a21c8c20>, <Future finished exception=JSONDecodeError('Expecting value: line 1 column 1 (char 0)')>)
Traceback (most recent call last):
  File "/usr/local/python3/lib/python3.7/site-packages/tornado/ioloop.py", line 743, in _run_callback
    ret = callback()
  File "/usr/local/python3/lib/python3.7/site-packages/tornado/tcpserver.py", line 327, in <lambda>
    gen.convert_yielded(future), lambda f: f.result()
  File "/usr/local/python3/lib/python3.7/site-packages/tornado/gen.py", line 748, in run
    yielded = self.gen.send(value)
  File "/home/Chunar/codes/Monitor_pi/motor_factory/fetch_data_server/socket_server.py", line 36, in handle_stream
    data_dict = json.loads(data.decode())
  File "/usr/local/python3/lib/python3.7/json/__init__.py", line 348, in loads
    return _default_decoder.decode(s)
  File "/usr/local/python3/lib/python3.7/json/decoder.py", line 337, in decode
    obj, end = self.raw_decode(s, idx=_w(s, 0).end())
  File "/usr/local/python3/lib/python3.7/json/decoder.py", line 355, in raw_decode
    raise JSONDecodeError("Expecting value", s, err.value) from None
json.decoder.JSONDecodeError: Expecting value: line 1 column 1 (char 0)
INFO:root:Socket served at time: Fri Nov  1 11:16:04 2019 with: ('58.213.153.13', 56504)
INFO:root:successfully connected ...
ERROR:tornado.application:Exception in callback functools.partial(<function TCPServer._handle_connection.<locals>.<lambda> at 0x7fc2a21c8dd0>, <Future finished exception=JSONDecodeError('Expecting value: line 1 column 1 (char 0)')>)
Traceback (most recent call last):
  File "/usr/local/python3/lib/python3.7/site-packages/tornado/ioloop.py", line 743, in _run_callback
    ret = callback()
  File "/usr/local/python3/lib/python3.7/site-packages/tornado/tcpserver.py", line 327, in <lambda>
    gen.convert_yielded(future), lambda f: f.result()
  File "/usr/local/python3/lib/python3.7/site-packages/tornado/gen.py", line 748, in run
    yielded = self.gen.send(value)
  File "/home/Chunar/codes/Monitor_pi/motor_factory/fetch_data_server/socket_server.py", line 36, in handle_stream
    data_dict = json.loads(data.decode())
  File "/usr/local/python3/lib/python3.7/json/__init__.py", line 348, in loads
    return _default_decoder.decode(s)
  File "/usr/local/python3/lib/python3.7/json/decoder.py", line 337, in decode
    obj, end = self.raw_decode(s, idx=_w(s, 0).end())
  File "/usr/local/python3/lib/python3.7/json/decoder.py", line 355, in raw_decode
    raise JSONDecodeError("Expecting value", s, err.value) from None
json.decoder.JSONDecodeError: Expecting value: line 1 column 1 (char 0)
INFO:root:Socket served at time: Fri Nov  1 11:16:11 2019 with: ('58.213.153.13', 56512)
INFO:root:successfully connected ...
ERROR:tornado.application:Exception in callback functools.partial(<function TCPServer._handle_connection.<locals>.<lambda> at 0x7fc2a21c8f80>, <Future finished exception=UnicodeDecodeError('utf-8', b'\x16\x03\x00\x00S\x01\x00\x00O\x03\x00?G\xd7\xf7\xba,\xee\xea\xb2`~\xf3\x00\xfd\x82{\xb9\xd5\x96\xc8w\x9b\xe6\xc4\xdb<=\xdbo\xef\x10n\x00\x00(\x00\x16\x00\x13\x00\n\x00f\x00\x05\x00\x04\x00e\x00d\x00c\x00b\x00a\x00`\x00\x15\x00\x12\x00\t\x00\x14\x00\x11\x00\x08\x00\x06\x00\x03\x01\x00', 13, 14, 'invalid continuation byte')>)
Traceback (most recent call last):
  File "/usr/local/python3/lib/python3.7/site-packages/tornado/ioloop.py", line 743, in _run_callback
    ret = callback()
  File "/usr/local/python3/lib/python3.7/site-packages/tornado/tcpserver.py", line 327, in <lambda>
    gen.convert_yielded(future), lambda f: f.result()
  File "/usr/local/python3/lib/python3.7/site-packages/tornado/gen.py", line 748, in run
    yielded = self.gen.send(value)
  File "/home/Chunar/codes/Monitor_pi/motor_factory/fetch_data_server/socket_server.py", line 36, in handle_stream
    data_dict = json.loads(data.decode())
UnicodeDecodeError: 'utf-8' codec can't decode byte 0xd7 in position 13: invalid continuation byte
INFO:root:Socket served at time: Fri Nov  1 11:16:16 2019 with: ('58.213.153.13', 56513)
INFO:root:successfully connected ...
ERROR:tornado.application:Exception in callback functools.partial(<function TCPServer._handle_connection.<locals>.<lambda> at 0x7fc2a2160200>, <Future finished exception=UnicodeDecodeError('utf-8', b'\x16\x03\x00\x00i\x01\x00\x00e\x03\x03U\x1c\xa7\xe4random1random2random3random4\x00\x00\x0c\x00/\x00\n\x00\x13\x009\x00\x04\x00\xff\x01\x00\x000\x00\r\x00,\x00*\x00\x01\x00\x03\x00\x02\x06\x01\x06\x03\x06\x02\x02\x01\x02\x03\x02\x02\x03\x01\x03\x03\x03\x02\x04\x01\x04\x03\x04\x02\x01\x01\x01\x03\x01\x02\x05\x01\x05\x03\x05\x02', 13, 14, 'invalid start byte')>)
Traceback (most recent call last):
  File "/usr/local/python3/lib/python3.7/site-packages/tornado/ioloop.py", line 743, in _run_callback
    ret = callback()
  File "/usr/local/python3/lib/python3.7/site-packages/tornado/tcpserver.py", line 327, in <lambda>
    gen.convert_yielded(future), lambda f: f.result()
  File "/usr/local/python3/lib/python3.7/site-packages/tornado/gen.py", line 748, in run
    yielded = self.gen.send(value)
  File "/home/Chunar/codes/Monitor_pi/motor_factory/fetch_data_server/socket_server.py", line 36, in handle_stream
    data_dict = json.loads(data.decode())
UnicodeDecodeError: 'utf-8' codec can't decode byte 0xa7 in position 13: invalid start byte
INFO:root:Socket served at time: Fri Nov  1 11:16:21 2019 with: ('58.213.153.13', 56515)
INFO:root:successfully connected ...
ERROR:tornado.application:Exception in callback functools.partial(<function TCPServer._handle_connection.<locals>.<lambda> at 0x7fc2a2160560>, <Future finished exception=UnicodeDecodeError('utf-8', b'\x00\x00\x00qj\x81n0\x81k\xa1\x03\x02\x01\x05\xa2\x03\x02\x01\n\xa4\x81^0\\\xa0\x07\x03\x05\x00P\x80\x00\x10\xa2\x04\x1b\x02NM\xa3\x170\x15\xa0\x03\x02\x01\x00\xa1\x0e0\x0c\x1b\x06krbtgt\x1b\x02NM\xa5\x11\x18\x0f19700101000000Z\xa7\x06\x02\x04\x1f\x1e\xb9\xd9\xa8\x170\x15\x02\x01\x12\x02\x01\x11\x02\x01\x10\x02\x01\x17\x02\x01\x01\x02\x01\x03\x02\x01\x02', 5, 6, 'invalid start byte')>)
Traceback (most recent call last):
  File "/usr/local/python3/lib/python3.7/site-packages/tornado/ioloop.py", line 743, in _run_callback
    ret = callback()
  File "/usr/local/python3/lib/python3.7/site-packages/tornado/tcpserver.py", line 327, in <lambda>
    gen.convert_yielded(future), lambda f: f.result()
  File "/usr/local/python3/lib/python3.7/site-packages/tornado/gen.py", line 748, in run
    yielded = self.gen.send(value)
  File "/home/Chunar/codes/Monitor_pi/motor_factory/fetch_data_server/socket_server.py", line 36, in handle_stream
    data_dict = json.loads(data.decode())
UnicodeDecodeError: 'utf-8' codec can't decode byte 0x81 in position 5: invalid start byte
INFO:root:Socket served at time: Fri Nov  1 11:16:26 2019 with: ('58.213.153.13', 56517)
INFO:root:successfully connected ...
ERROR:tornado.application:Exception in callback functools.partial(<function TCPServer._handle_connection.<locals>.<lambda> at 0x7fc2a21607a0>, <Future finished exception=UnicodeDecodeError('utf-8', b'\x00\x00\x00\xa4\xffSMBr\x00\x00\x00\x00\x08\x01@\x00\x00\x00\x00\x00\x00\x00\x00\x00\x00\x00\x00\x00\x00@\x06\x00\x00\x01\x00\x00\x81\x00\x02PC NETWORK PROGRAM 1.0\x00\x02MICROSOFT NETWORKS 1.03\x00\x02MICROSOFT NETWORKS 3.0\x00\x02LANMAN1.0\x00\x02LM1.2X002\x00\x02Samba\x00\x02NT LANMAN 1.0\x00\x02NT LM 0.12\x00', 3, 4, 'invalid start byte')>)
Traceback (most recent call last):
  File "/usr/local/python3/lib/python3.7/site-packages/tornado/ioloop.py", line 743, in _run_callback
    ret = callback()
  File "/usr/local/python3/lib/python3.7/site-packages/tornado/tcpserver.py", line 327, in <lambda>
    gen.convert_yielded(future), lambda f: f.result()
  File "/usr/local/python3/lib/python3.7/site-packages/tornado/gen.py", line 748, in run
    yielded = self.gen.send(value)
  File "/home/Chunar/codes/Monitor_pi/motor_factory/fetch_data_server/socket_server.py", line 36, in handle_stream
    data_dict = json.loads(data.decode())
UnicodeDecodeError: 'utf-8' codec can't decode byte 0xa4 in position 3: invalid start byte
INFO:root:Socket served at time: Fri Nov  1 11:16:31 2019 with: ('58.213.153.13', 56519)
INFO:root:successfully connected ...
ERROR:tornado.application:Exception in callback functools.partial(<function TCPServer._handle_connection.<locals>.<lambda> at 0x7fc2a21609e0>, <Future finished exception=JSONDecodeError('Expecting value: line 1 column 1 (char 0)')>)
Traceback (most recent call last):
  File "/usr/local/python3/lib/python3.7/site-packages/tornado/ioloop.py", line 743, in _run_callback
    ret = callback()
  File "/usr/local/python3/lib/python3.7/site-packages/tornado/tcpserver.py", line 327, in <lambda>
    gen.convert_yielded(future), lambda f: f.result()
  File "/usr/local/python3/lib/python3.7/site-packages/tornado/gen.py", line 748, in run
    yielded = self.gen.send(value)
  File "/home/Chunar/codes/Monitor_pi/motor_factory/fetch_data_server/socket_server.py", line 36, in handle_stream
    data_dict = json.loads(data.decode())
  File "/usr/local/python3/lib/python3.7/json/__init__.py", line 348, in loads
    return _default_decoder.decode(s)
  File "/usr/local/python3/lib/python3.7/json/decoder.py", line 337, in decode
    obj, end = self.raw_decode(s, idx=_w(s, 0).end())
  File "/usr/local/python3/lib/python3.7/json/decoder.py", line 355, in raw_decode
    raise JSONDecodeError("Expecting value", s, err.value) from None
json.decoder.JSONDecodeError: Expecting value: line 1 column 1 (char 0)
INFO:root:Socket served at time: Fri Nov  1 11:16:36 2019 with: ('58.213.153.13', 56521)
INFO:root:successfully connected ...
ERROR:tornado.application:Exception in callback functools.partial(<function TCPServer._handle_connection.<locals>.<lambda> at 0x7fc2a2160b90>, <Future finished exception=JSONDecodeError('Expecting value: line 1 column 1 (char 0)')>)
Traceback (most recent call last):
  File "/usr/local/python3/lib/python3.7/site-packages/tornado/ioloop.py", line 743, in _run_callback
    ret = callback()
  File "/usr/local/python3/lib/python3.7/site-packages/tornado/tcpserver.py", line 327, in <lambda>
    gen.convert_yielded(future), lambda f: f.result()
  File "/usr/local/python3/lib/python3.7/site-packages/tornado/gen.py", line 748, in run
    yielded = self.gen.send(value)
  File "/home/Chunar/codes/Monitor_pi/motor_factory/fetch_data_server/socket_server.py", line 36, in handle_stream
    data_dict = json.loads(data.decode())
  File "/usr/local/python3/lib/python3.7/json/__init__.py", line 348, in loads
    return _default_decoder.decode(s)
  File "/usr/local/python3/lib/python3.7/json/decoder.py", line 337, in decode
    obj, end = self.raw_decode(s, idx=_w(s, 0).end())
  File "/usr/local/python3/lib/python3.7/json/decoder.py", line 355, in raw_decode
    raise JSONDecodeError("Expecting value", s, err.value) from None
json.decoder.JSONDecodeError: Expecting value: line 1 column 1 (char 0)
INFO:root:Socket served at time: Fri Nov  1 11:16:41 2019 with: ('58.213.153.13', 56523)
INFO:root:successfully connected ...
ERROR:tornado.application:Exception in callback functools.partial(<function TCPServer._handle_connection.<locals>.<lambda> at 0x7fc2a2160d40>, <Future finished exception=JSONDecodeError('Expecting value: line 1 column 1 (char 0)')>)
Traceback (most recent call last):
  File "/usr/local/python3/lib/python3.7/site-packages/tornado/ioloop.py", line 743, in _run_callback
    ret = callback()
  File "/usr/local/python3/lib/python3.7/site-packages/tornado/tcpserver.py", line 327, in <lambda>
    gen.convert_yielded(future), lambda f: f.result()
  File "/usr/local/python3/lib/python3.7/site-packages/tornado/gen.py", line 748, in run
    yielded = self.gen.send(value)
  File "/home/Chunar/codes/Monitor_pi/motor_factory/fetch_data_server/socket_server.py", line 36, in handle_stream
    data_dict = json.loads(data.decode())
  File "/usr/local/python3/lib/python3.7/json/__init__.py", line 348, in loads
    return _default_decoder.decode(s)
  File "/usr/local/python3/lib/python3.7/json/decoder.py", line 337, in decode
    obj, end = self.raw_decode(s, idx=_w(s, 0).end())
  File "/usr/local/python3/lib/python3.7/json/decoder.py", line 355, in raw_decode
    raise JSONDecodeError("Expecting value", s, err.value) from None
json.decoder.JSONDecodeError: Expecting value: line 1 column 1 (char 0)
INFO:root:Socket served at time: Fri Nov  1 11:16:47 2019 with: ('58.213.153.13', 56525)
INFO:root:successfully connected ...
ERROR:tornado.application:Exception in callback functools.partial(<function TCPServer._handle_connection.<locals>.<lambda> at 0x7fc2a21c8f80>, <Future finished exception=UnicodeDecodeError('utf-8', b'0\x84\x00\x00\x00-\x02\x01\x07c\x84\x00\x00\x00$\x04\x00\n\x01\x00\n\x01\x00\x02\x01\x00\x02\x01d\x01\x01\x00\x87\x0bobjectClass0\x84\x00\x00\x00\x00', 1, 2, 'invalid start byte')>)
Traceback (most recent call last):
  File "/usr/local/python3/lib/python3.7/site-packages/tornado/ioloop.py", line 743, in _run_callback
    ret = callback()
  File "/usr/local/python3/lib/python3.7/site-packages/tornado/tcpserver.py", line 327, in <lambda>
    gen.convert_yielded(future), lambda f: f.result()
  File "/usr/local/python3/lib/python3.7/site-packages/tornado/gen.py", line 748, in run
    yielded = self.gen.send(value)
  File "/home/Chunar/codes/Monitor_pi/motor_factory/fetch_data_server/socket_server.py", line 36, in handle_stream
    data_dict = json.loads(data.decode())
UnicodeDecodeError: 'utf-8' codec can't decode byte 0x84 in position 1: invalid start byte
INFO:root:Socket served at time: Fri Nov  1 11:16:52 2019 with: ('58.213.153.13', 56527)
INFO:root:successfully connected ...
ERROR:tornado.application:Exception in callback functools.partial(<function TCPServer._handle_connection.<locals>.<lambda> at 0x7fc2a21c8dd0>, <Future finished exception=UnicodeDecodeError('utf-8', b'0\x0c\x02\x01\x01`\x07\x02\x01\x02\x04\x00\x80\x00', 12, 13, 'invalid start byte')>)
Traceback (most recent call last):
  File "/usr/local/python3/lib/python3.7/site-packages/tornado/ioloop.py", line 743, in _run_callback
    ret = callback()
  File "/usr/local/python3/lib/python3.7/site-packages/tornado/tcpserver.py", line 327, in <lambda>
    gen.convert_yielded(future), lambda f: f.result()
  File "/usr/local/python3/lib/python3.7/site-packages/tornado/gen.py", line 748, in run
    yielded = self.gen.send(value)
  File "/home/Chunar/codes/Monitor_pi/motor_factory/fetch_data_server/socket_server.py", line 36, in handle_stream
    data_dict = json.loads(data.decode())
UnicodeDecodeError: 'utf-8' codec can't decode byte 0x80 in position 12: invalid start byte
INFO:root:Socket served at time: Fri Nov  1 11:16:57 2019 with: ('58.213.153.13', 56529)
INFO:root:successfully connected ...
ERROR:tornado.application:Exception in callback functools.partial(<function TCPServer._handle_connection.<locals>.<lambda> at 0x7fc2a21c89e0>, <Future finished exception=JSONDecodeError('Expecting value: line 1 column 1 (char 0)')>)
Traceback (most recent call last):
  File "/usr/local/python3/lib/python3.7/site-packages/tornado/ioloop.py", line 743, in _run_callback
    ret = callback()
  File "/usr/local/python3/lib/python3.7/site-packages/tornado/tcpserver.py", line 327, in <lambda>
    gen.convert_yielded(future), lambda f: f.result()
  File "/usr/local/python3/lib/python3.7/site-packages/tornado/gen.py", line 748, in run
    yielded = self.gen.send(value)
  File "/home/Chunar/codes/Monitor_pi/motor_factory/fetch_data_server/socket_server.py", line 36, in handle_stream
    data_dict = json.loads(data.decode())
  File "/usr/local/python3/lib/python3.7/json/__init__.py", line 348, in loads
    return _default_decoder.decode(s)
  File "/usr/local/python3/lib/python3.7/json/decoder.py", line 337, in decode
    obj, end = self.raw_decode(s, idx=_w(s, 0).end())
  File "/usr/local/python3/lib/python3.7/json/decoder.py", line 355, in raw_decode
    raise JSONDecodeError("Expecting value", s, err.value) from None
json.decoder.JSONDecodeError: Expecting value: line 1 column 1 (char 0)
INFO:root:Socket served at time: Fri Nov  1 11:17:04 2019 with: ('58.213.153.13', 56532)
INFO:root:successfully connected ...
ERROR:tornado.application:Exception in callback functools.partial(<function TCPServer._handle_connection.<locals>.<lambda> at 0x7fc2a21c87a0>, <Future finished exception=JSONDecodeError('Expecting value: line 1 column 1 (char 0)')>)
Traceback (most recent call last):
  File "/usr/local/python3/lib/python3.7/site-packages/tornado/ioloop.py", line 743, in _run_callback
    ret = callback()
  File "/usr/local/python3/lib/python3.7/site-packages/tornado/tcpserver.py", line 327, in <lambda>
    gen.convert_yielded(future), lambda f: f.result()
  File "/usr/local/python3/lib/python3.7/site-packages/tornado/gen.py", line 748, in run
    yielded = self.gen.send(value)
  File "/home/Chunar/codes/Monitor_pi/motor_factory/fetch_data_server/socket_server.py", line 36, in handle_stream
    data_dict = json.loads(data.decode())
  File "/usr/local/python3/lib/python3.7/json/__init__.py", line 348, in loads
    return _default_decoder.decode(s)
  File "/usr/local/python3/lib/python3.7/json/decoder.py", line 337, in decode
    obj, end = self.raw_decode(s, idx=_w(s, 0).end())
  File "/usr/local/python3/lib/python3.7/json/decoder.py", line 355, in raw_decode
    raise JSONDecodeError("Expecting value", s, err.value) from None
json.decoder.JSONDecodeError: Expecting value: line 1 column 1 (char 0)
INFO:root:Socket served at time: Fri Nov  1 11:17:09 2019 with: ('58.213.153.13', 56534)
INFO:root:successfully connected ...
ERROR:tornado.application:Exception in callback functools.partial(<function TCPServer._handle_connection.<locals>.<lambda> at 0x7fc2a21c8710>, <Future finished exception=UnicodeDecodeError('utf-8', b'\x03\x00\x00\x0b\x06\xe0\x00\x00\x00\x00\x00', 5, 6, 'invalid continuation byte')>)
Traceback (most recent call last):
  File "/usr/local/python3/lib/python3.7/site-packages/tornado/ioloop.py", line 743, in _run_callback
    ret = callback()
  File "/usr/local/python3/lib/python3.7/site-packages/tornado/tcpserver.py", line 327, in <lambda>
    gen.convert_yielded(future), lambda f: f.result()
  File "/usr/local/python3/lib/python3.7/site-packages/tornado/gen.py", line 748, in run
    yielded = self.gen.send(value)
  File "/home/Chunar/codes/Monitor_pi/motor_factory/fetch_data_server/socket_server.py", line 36, in handle_stream
    data_dict = json.loads(data.decode())
UnicodeDecodeError: 'utf-8' codec can't decode byte 0xe0 in position 5: invalid continuation byte
INFO:root:Socket served at time: Fri Nov  1 11:17:14 2019 with: ('58.213.153.13', 56536)
INFO:root:successfully connected ...
ERROR:tornado.application:Exception in callback functools.partial(<function TCPServer._handle_connection.<locals>.<lambda> at 0x7fc2a21c8440>, <Future finished exception=UnicodeDecodeError('utf-8', b'DmdT\x00\x00\x00\x17\x00\x00\x00\x01\x00\x00\x00\x00\x11\x11\x00\xff\x01\xff\x13', 19, 20, 'invalid start byte')>)
Traceback (most recent call last):
  File "/usr/local/python3/lib/python3.7/site-packages/tornado/ioloop.py", line 743, in _run_callback
    ret = callback()
  File "/usr/local/python3/lib/python3.7/site-packages/tornado/tcpserver.py", line 327, in <lambda>
    gen.convert_yielded(future), lambda f: f.result()
  File "/usr/local/python3/lib/python3.7/site-packages/tornado/gen.py", line 748, in run
    yielded = self.gen.send(value)
  File "/home/Chunar/codes/Monitor_pi/motor_factory/fetch_data_server/socket_server.py", line 36, in handle_stream
    data_dict = json.loads(data.decode())
UnicodeDecodeError: 'utf-8' codec can't decode byte 0xff in position 19: invalid start byte
INFO:root:Socket served at time: Fri Nov  1 11:17:19 2019 with: ('58.213.153.13', 56537)
INFO:root:successfully connected ...
ERROR:tornado.application:Exception in callback functools.partial(<function TCPServer._handle_connection.<locals>.<lambda> at 0x7fc2a21c8320>, <Future finished exception=JSONDecodeError('Expecting value: line 1 column 1 (char 0)')>)
Traceback (most recent call last):
  File "/usr/local/python3/lib/python3.7/site-packages/tornado/ioloop.py", line 743, in _run_callback
    ret = callback()
  File "/usr/local/python3/lib/python3.7/site-packages/tornado/tcpserver.py", line 327, in <lambda>
    gen.convert_yielded(future), lambda f: f.result()
  File "/usr/local/python3/lib/python3.7/site-packages/tornado/gen.py", line 748, in run
    yielded = self.gen.send(value)
  File "/home/Chunar/codes/Monitor_pi/motor_factory/fetch_data_server/socket_server.py", line 36, in handle_stream
    data_dict = json.loads(data.decode())
  File "/usr/local/python3/lib/python3.7/json/__init__.py", line 348, in loads
    return _default_decoder.decode(s)
  File "/usr/local/python3/lib/python3.7/json/decoder.py", line 337, in decode
    obj, end = self.raw_decode(s, idx=_w(s, 0).end())
  File "/usr/local/python3/lib/python3.7/json/decoder.py", line 355, in raw_decode
    raise JSONDecodeError("Expecting value", s, err.value) from None
json.decoder.JSONDecodeError: Expecting value: line 1 column 1 (char 0)
INFO:root:Socket served at time: Fri Nov  1 11:17:24 2019 with: ('58.213.153.13', 56539)
INFO:root:successfully connected ...
ERROR:tornado.application:Exception in callback functools.partial(<function TCPServer._handle_connection.<locals>.<lambda> at 0x7fc2a2160a70>, <Future finished exception=JSONDecodeError('Expecting value: line 1 column 1 (char 0)')>)
Traceback (most recent call last):
  File "/usr/local/python3/lib/python3.7/site-packages/tornado/ioloop.py", line 743, in _run_callback
    ret = callback()
  File "/usr/local/python3/lib/python3.7/site-packages/tornado/tcpserver.py", line 327, in <lambda>
    gen.convert_yielded(future), lambda f: f.result()
  File "/usr/local/python3/lib/python3.7/site-packages/tornado/gen.py", line 748, in run
    yielded = self.gen.send(value)
  File "/home/Chunar/codes/Monitor_pi/motor_factory/fetch_data_server/socket_server.py", line 36, in handle_stream
    data_dict = json.loads(data.decode())
  File "/usr/local/python3/lib/python3.7/json/__init__.py", line 348, in loads
    return _default_decoder.decode(s)
  File "/usr/local/python3/lib/python3.7/json/decoder.py", line 337, in decode
    obj, end = self.raw_decode(s, idx=_w(s, 0).end())
  File "/usr/local/python3/lib/python3.7/json/decoder.py", line 355, in raw_decode
    raise JSONDecodeError("Expecting value", s, err.value) from None
json.decoder.JSONDecodeError: Expecting value: line 1 column 1 (char 0)
INFO:root:Socket served at time: Fri Nov  1 11:17:29 2019 with: ('58.213.153.13', 56541)
INFO:root:successfully connected ...
ERROR:tornado.application:Exception in callback functools.partial(<function TCPServer._handle_connection.<locals>.<lambda> at 0x7fc2a21608c0>, <Future finished exception=UnicodeDecodeError('utf-8', b'\x01\x00\x00\xfd\xce\xfa\x0b\xb0\xa0\x00\x00\x00MMS\x14\x00\x00\x00\x00\x00\x00\x00\x00\x00\x00\x00\x00\x00\x00\x00\x12\x00\x00\x00\x01\x00\x03\x00\xf0\xf0\xf0\xf0\x0b\x00\x04\x00\x1c\x00\x03\x00N\x00S\x00P\x00l\x00a\x00y\x00e\x00r\x00/\x009\x00.\x000\x00.\x000\x00.\x002\x009\x008\x000\x00;\x00 \x00{\x000\x000\x000\x000\x00A\x00A\x000\x000\x00-\x000\x00A\x000\x000\x00-\x000\x000\x00a\x000\x00-\x00A\x00A\x000\x00A\x00-\x000\x000\x000\x000\x00A\x000\x00A\x00A\x000\x00A\x00A\x000\x00}\x00\x00\x00\xe0m\xdf_', 3, 4, 'invalid start byte')>)
Traceback (most recent call last):
  File "/usr/local/python3/lib/python3.7/site-packages/tornado/ioloop.py", line 743, in _run_callback
    ret = callback()
  File "/usr/local/python3/lib/python3.7/site-packages/tornado/tcpserver.py", line 327, in <lambda>
    gen.convert_yielded(future), lambda f: f.result()
  File "/usr/local/python3/lib/python3.7/site-packages/tornado/gen.py", line 748, in run
    yielded = self.gen.send(value)
  File "/home/Chunar/codes/Monitor_pi/motor_factory/fetch_data_server/socket_server.py", line 36, in handle_stream
    data_dict = json.loads(data.decode())
UnicodeDecodeError: 'utf-8' codec can't decode byte 0xfd in position 3: invalid start byte
INFO:root:Socket served at time: Fri Nov  1 11:17:34 2019 with: ('58.213.153.13', 56543)
INFO:root:successfully connected ...
ERROR:tornado.application:Exception in callback functools.partial(<function TCPServer._handle_connection.<locals>.<lambda> at 0x7fc2a21607a0>, <Future finished exception=UnicodeDecodeError('utf-8', b'\x00Z\x00\x00\x01\x00\x00\x00\x016\x01,\x00\x00\x08\x00\x7f\xff\x7f\x08\x00\x00\x00\x01\x00 \x00:\x00\x00\x00\x00\x00\x00\x00\x00\x00\x00\x00\x00\x00\x00\x00\x004\xe6\x00\x00\x00\x01\x00\x00\x00\x00\x00\x00\x00\x00(CONNECT_DATA=(COMMAND=version))', 17, 18, 'invalid start byte')>)
Traceback (most recent call last):
  File "/usr/local/python3/lib/python3.7/site-packages/tornado/ioloop.py", line 743, in _run_callback
    ret = callback()
  File "/usr/local/python3/lib/python3.7/site-packages/tornado/tcpserver.py", line 327, in <lambda>
    gen.convert_yielded(future), lambda f: f.result()
  File "/usr/local/python3/lib/python3.7/site-packages/tornado/gen.py", line 748, in run
    yielded = self.gen.send(value)
  File "/home/Chunar/codes/Monitor_pi/motor_factory/fetch_data_server/socket_server.py", line 36, in handle_stream
    data_dict = json.loads(data.decode())
UnicodeDecodeError: 'utf-8' codec can't decode byte 0xff in position 17: invalid start byte
INFO:root:Socket served at time: Fri Nov  1 11:17:39 2019 with: ('58.213.153.13', 56571)
INFO:root:successfully connected ...
ERROR:tornado.application:Exception in callback functools.partial(<function TCPServer._handle_connection.<locals>.<lambda> at 0x7fc2a2160560>, <Future finished exception=UnicodeDecodeError('utf-8', b'\x12\x01\x004\x00\x00\x00\x00\x00\x00\x15\x00\x06\x01\x00\x1b\x00\x01\x02\x00\x1c\x00\x0c\x03\x00(\x00\x04\xff\x08\x00\x01U\x00\x00\x00MSSQLServer\x00H\x0f\x00\x00', 28, 29, 'invalid start byte')>)
Traceback (most recent call last):
  File "/usr/local/python3/lib/python3.7/site-packages/tornado/ioloop.py", line 743, in _run_callback
    ret = callback()
  File "/usr/local/python3/lib/python3.7/site-packages/tornado/tcpserver.py", line 327, in <lambda>
    gen.convert_yielded(future), lambda f: f.result()
  File "/usr/local/python3/lib/python3.7/site-packages/tornado/gen.py", line 748, in run
    yielded = self.gen.send(value)
  File "/home/Chunar/codes/Monitor_pi/motor_factory/fetch_data_server/socket_server.py", line 36, in handle_stream
    data_dict = json.loads(data.decode())
UnicodeDecodeError: 'utf-8' codec can't decode byte 0xff in position 28: invalid start byte
INFO:root:Socket served at time: Fri Nov  1 11:17:44 2019 with: ('58.213.153.13', 56579)
INFO:root:successfully connected ...
ERROR:tornado.application:Exception in callback functools.partial(<function TCPServer._handle_connection.<locals>.<lambda> at 0x7fc2a2160200>, <Future finished exception=JSONDecodeError('Expecting value: line 1 column 1 (char 0)')>)
Traceback (most recent call last):
  File "/usr/local/python3/lib/python3.7/site-packages/tornado/ioloop.py", line 743, in _run_callback
    ret = callback()
  File "/usr/local/python3/lib/python3.7/site-packages/tornado/tcpserver.py", line 327, in <lambda>
    gen.convert_yielded(future), lambda f: f.result()
  File "/usr/local/python3/lib/python3.7/site-packages/tornado/gen.py", line 748, in run
    yielded = self.gen.send(value)
  File "/home/Chunar/codes/Monitor_pi/motor_factory/fetch_data_server/socket_server.py", line 36, in handle_stream
    data_dict = json.loads(data.decode())
  File "/usr/local/python3/lib/python3.7/json/__init__.py", line 348, in loads
    return _default_decoder.decode(s)
  File "/usr/local/python3/lib/python3.7/json/decoder.py", line 337, in decode
    obj, end = self.raw_decode(s, idx=_w(s, 0).end())
  File "/usr/local/python3/lib/python3.7/json/decoder.py", line 355, in raw_decode
    raise JSONDecodeError("Expecting value", s, err.value) from None
json.decoder.JSONDecodeError: Expecting value: line 1 column 1 (char 0)
INFO:root:Socket served at time: Fri Nov  1 11:17:49 2019 with: ('58.213.153.13', 56627)
INFO:root:successfully connected ...
ERROR:tornado.application:Exception in callback functools.partial(<function TCPServer._handle_connection.<locals>.<lambda> at 0x7fc2a2160290>, <Future finished exception=JSONDecodeError('Expecting value: line 1 column 1 (char 0)')>)
Traceback (most recent call last):
  File "/usr/local/python3/lib/python3.7/site-packages/tornado/ioloop.py", line 743, in _run_callback
    ret = callback()
  File "/usr/local/python3/lib/python3.7/site-packages/tornado/tcpserver.py", line 327, in <lambda>
    gen.convert_yielded(future), lambda f: f.result()
  File "/usr/local/python3/lib/python3.7/site-packages/tornado/gen.py", line 748, in run
    yielded = self.gen.send(value)
  File "/home/Chunar/codes/Monitor_pi/motor_factory/fetch_data_server/socket_server.py", line 36, in handle_stream
    data_dict = json.loads(data.decode())
  File "/usr/local/python3/lib/python3.7/json/__init__.py", line 348, in loads
    return _default_decoder.decode(s)
  File "/usr/local/python3/lib/python3.7/json/decoder.py", line 337, in decode
    obj, end = self.raw_decode(s, idx=_w(s, 0).end())
  File "/usr/local/python3/lib/python3.7/json/decoder.py", line 355, in raw_decode
    raise JSONDecodeError("Expecting value", s, err.value) from None
json.decoder.JSONDecodeError: Expecting value: line 1 column 1 (char 0)
INFO:root:Socket served at time: Fri Nov  1 11:17:58 2019 with: ('58.213.153.13', 56689)
INFO:root:successfully connected ...
INFO:root:Socket served at time: Fri Nov  1 11:17:58 2019 with: ('58.213.153.13', 56699)
INFO:root:successfully connected ...
ERROR:tornado.application:Exception in callback functools.partial(<function TCPServer._handle_connection.<locals>.<lambda> at 0x7fc2a21555f0>, <Future finished exception=JSONDecodeError('Expecting value: line 1 column 1 (char 0)')>)
Traceback (most recent call last):
  File "/usr/local/python3/lib/python3.7/site-packages/tornado/ioloop.py", line 743, in _run_callback
    ret = callback()
  File "/usr/local/python3/lib/python3.7/site-packages/tornado/tcpserver.py", line 327, in <lambda>
    gen.convert_yielded(future), lambda f: f.result()
  File "/usr/local/python3/lib/python3.7/site-packages/tornado/gen.py", line 748, in run
    yielded = self.gen.send(value)
  File "/home/Chunar/codes/Monitor_pi/motor_factory/fetch_data_server/socket_server.py", line 36, in handle_stream
    data_dict = json.loads(data.decode())
  File "/usr/local/python3/lib/python3.7/json/__init__.py", line 348, in loads
    return _default_decoder.decode(s)
  File "/usr/local/python3/lib/python3.7/json/decoder.py", line 337, in decode
    obj, end = self.raw_decode(s, idx=_w(s, 0).end())
  File "/usr/local/python3/lib/python3.7/json/decoder.py", line 355, in raw_decode
    raise JSONDecodeError("Expecting value", s, err.value) from None
json.decoder.JSONDecodeError: Expecting value: line 1 column 1 (char 0)
INFO:root:Server finished
INFO:root:*************************
INFO:root:Socket served at time: Fri Nov  1 11:18:09 2019 with: ('58.213.153.13', 590)
INFO:root:successfully connected ...
ERROR:tornado.application:Exception in callback functools.partial(<function TCPServer._handle_connection.<locals>.<lambda> at 0x7fc2a21554d0>, <Future finished exception=UnicodeDecodeError('utf-8', b'\x80\x00\x00(*\xf8\xab\xda\x00\x00\x00\x00\x00\x00\x00\x02\x00\x01\x86\xa0\x00\x00\x00\x02\x00\x00\x00\x00\x00\x00\x00\x00\x00\x00\x00\x00\x00\x00\x00\x00\x00\x00\x00\x00', 0, 1, 'invalid start byte')>)
Traceback (most recent call last):
  File "/usr/local/python3/lib/python3.7/site-packages/tornado/ioloop.py", line 743, in _run_callback
    ret = callback()
  File "/usr/local/python3/lib/python3.7/site-packages/tornado/tcpserver.py", line 327, in <lambda>
    gen.convert_yielded(future), lambda f: f.result()
  File "/usr/local/python3/lib/python3.7/site-packages/tornado/gen.py", line 748, in run
    yielded = self.gen.send(value)
  File "/home/Chunar/codes/Monitor_pi/motor_factory/fetch_data_server/socket_server.py", line 36, in handle_stream
    data_dict = json.loads(data.decode())
UnicodeDecodeError: 'utf-8' codec can't decode byte 0x80 in position 0: invalid start byte
INFO:root:Socket served at time: Sun Nov  3 21:25:01 2019 with: ('219.217.153.78', 9893)
INFO:root:successfully connected ...
INFO:root:successfully connected ...
INFO:root:successfully connected ...
INFO:root:successfully connected ...
INFO:root:Server finished
INFO:root:*************************
INFO:root:Socket served at time: Sun Nov  3 21:42:23 2019 with: ('219.217.153.78', 10041)
INFO:root:successfully connected ...
INFO:root:successfully connected ...
INFO:root:successfully connected ...
INFO:root:successfully connected ...
INFO:root:Server finished
INFO:root:*************************
